Workbook

Sheet Programmming Fundamental
B1: =[1]Theory!A1 -> MNS - UNIVERSITY OF ENGINEERING AND TECHNOLOGY MULTAN | L1: =[1]Theory!B4 -> Fall-2023-2027 (Evening-A) | P1: =[1]Theory!H3 -> 1st Semester | S1: =[1]Theory!H4 -> Fall 2023 | X1: =[1]Theory!H5 -> Engr. M Talha Jahangir
B2: Activity Sheet | I2: =[1]Theory!B3 -> BS Information Technology | R2: CLO & PLO Assessment
B3: Subject: | E3: =[1]Theory!B5 -> Title (Code): Programming Fundamental (IT-111)
B4: Component Name | E4: Quiz 1 | F4: Mid Term | J4: C.P | K4: Quiz 2 | L4: Final Term | P4: Total | Q4: Grade | R4: CLOs vs. PLOs
B5: Total Marks | E5: 10 | F5: 30 | J5: 10 | K5: 10 | L5: 16 | M5: 14 | N5: 10 | O5: 40 | P5: =SUM(E5:N5) -> 100 | R5: CLOs | S5: 1 | T5: 2 | U5: 3
B6: Question Components | E6: Q 1 | F6: Q1 | G6: Q2 | H6: Q3 | I6: Total | J6: Q1 | K6: Q1 | L6: Q1 | M6: Q2 | N6: Q3 | O6: Total | R6: PLOs | S6: 2 | T6: 2 | U6: 4
B7: Component Marks | E7: 10 | F7: 10 | G7: 10 | H7: 10 | I7: =F7+G7+H7 -> 30 | J7: 10 | K7: 10 | L7: 10 | M7: 14 | N7: 16 | O7: 40 | P7: =SUM(E7:H7,J7:N7) -> 100 | S7: =U7+F7+E7+L7 -> 56 | T7: =G7+H7+K7+M7 -> 44 | U7: =J7+N7 -> 26
D8: KPI | E8: =E7*0.5 -> 5 | F8: =F7*0.5 -> 5 | G8: =G7*0.5 -> 5 | H8: =H7*0.5 -> 5 | I8: =I7*0.5 -> 15 | J8: =J7*0.5 -> 5 | K8: =K7*0.5 -> 5 | L8: =L7*0.5 -> 5 | ... O8: =O7*0.5 -> 20 | P8: =SUM(E8:H8)+SUM(J8:J8)+SUM(K8:N8) -> 50 | S8: Assessment of CLOs | V8: PLOs Acheivement | Y8: PLOs Acheivement
D9: CLO Mapping | E9: 1 | F9: 1 | G9: 2 | H9: 2 | J9: 3 | K9: 2 | L9: 1 | M9: 2 | N9: 3 | S9: =S5 -> 1 | T9: =T5 -> 2 | U9: 3 | V9: 2 | W9: 2 | X9: 4 | Y9: =S6 -> 2 | Z9: =T6 -> 2 | AA9: =U6 -> 4
B10: Sr. No. | C10: Registration No. | D10: Student Name | Y10: Y | Z10: N
B11: 1 | C11: =[1]Theory!A25 -> 2023-IT-01 | D11: =[1]Theory!B25 -> Rahma Noor | E11: =[1]Theory!D25 -> 10 | F11: 4 | G11: 5 | H11: 5 | I11: =[1]Theory!E25 -> 14 | J11: =[1]Theory!H25 -> 9 | K11: =[1]Theory!F25 -> 9 | L11: 6 | M11: 6 | N11: 6 | O11: =[1]Theory!G25 -> 18 | P11: =E11+I11+J11+K11+O11 -> 60 | Q11: =[1]Theory!J25 -> B | S11: =E11+F11+L11 -> 20 | T11: =G11+H11+K11+M11 -> 25 | U11: =J11+N11 -> 15 | V11: =((S11/$S$7)*100) -> 35.714286 | W11: =((T11/$T$7)*100) -> 56.818182 | X11: =((U11/$U$7)*100) -> 57.692308 | Y11: =IF(V11>=50,"Y","N") -> N | Z11: =IF(W11>=50,"Y","N") -> Y | AA11: =IF(X11>=50,"Y","N") -> Y
B12: 2 | C12: =[1]Theory!A26 -> 2023-IT-02 | D12: =[1]Theory!B26 -> Alishba Manzoor | E12: =[1]Theory!D26 -> 8 | F12: 7 | G12: 8 | H12: 6 | I12: =[1]Theory!E26 -> 21 | J12: =[1]Theory!H26 -> 8 | K12: =[1]Theory!F26 -> 7 | L12: 5 | M12: 7 | N12: 8 | O12: =[1]Theory!G26 -> 20 | P12: =E12+I12+J12+K12+O12 -> 64 | Q12: =[1]Theory!J26 -> B | S12: =E12+F12+L12 -> 20 | T12: =G12+H12+K12+M12 -> 28 | U12: =J12+N12 -> 16 | V12: =((S12/$S$7)*100) -> 35.714286 | W12: =((T12/$T$7)*100) -> 63.636364 | X12: =((U12/$U$7)*100) -> 61.538462 | Y12: =IF(V12>=50,"Y","N") -> N | Z12: =IF(W12>=50,"Y","N") -> Y | AA12: =IF(X12>=50,"Y","N") -> Y
B13: 3 | C13: =[1]Theory!A27 -> 2023-IT-03 | D13: =[1]Theory!B27 -> Maheen Fatima | E13: =[1]Theory!D27 -> 8 | F13: 1 | G13: 5 | H13: 6 | I13: =[1]Theory!E27 -> 12 | J13: =[1]Theory!H27 -> 8 | K13: =[1]Theory!F27 -> 9 | L13: 6 | M13: 6 | N13: 9 | O13: =[1]Theory!G27 -> 21 | P13: =E13+I13+J13+K13+O13 -> 58 | Q13: =[1]Theory!J27 -> B- | S13: =E13+F13+L13 -> 15 | T13: =G13+H13+K13+M13 -> 26 | U13: =J13+N13 -> 17 | V13: =((S13/$S$7)*100) -> 26.785714 | W13: =((T13/$T$7)*100) -> 59.090909 | X13: =((U13/$U$7)*100) -> 65.384615 | Y13: =IF(V13>=50,"Y","N") -> N | Z13: =IF(W13>=50,"Y","N") -> Y | AA13: =IF(X13>=50,"Y","N") -> Y
B14: 4 | C14: =[1]Theory!A28 -> 2023-IT-04 | D14: =[1]Theory!B28 -> Aneela | E14: =[1]Theory!D28 -> 9 | F14: 6 | G14: 6 | H14: 6 | I14: =[1]Theory!E28 -> 18 | J14: =[1]Theory!H28 -> 9 | K14: =[1]Theory!F28 -> 8 | L14: 5 | M14: 11 | N14: 6 | O14: =[1]Theory!G28 -> 22 | P14: =E14+I14+J14+K14+O14 -> 66 | Q14: =[1]Theory!J28 -> B+ | S14: =E14+F14+L14 -> 20 | T14: =G14+H14+K14+M14 -> 31 | U14: =J14+N14 -> 15 | V14: =((S14/$S$7)*100) -> 35.714286 | W14: =((T14/$T$7)*100) -> 70.454545 | X14: =((U14/$U$7)*100) -> 57.692308 | Y14: =IF(V14>=50,"Y","N") -> N | Z14: =IF(W14>=50,"Y","N") -> Y | AA14: =IF(X14>=50,"Y","N") -> Y
B15: 5 | C15: =[1]Theory!A29 -> 2023-IT-05 | D15: =[1]Theory!B29 -> Alishba Saleem | E15: =[1]Theory!D29 -> 8 | F15: 0 | G15: 5 | H15: 5 | I15: =[1]Theory!E29 -> 10 | J15: =[1]Theory!H29 -> 9 | K15: =[1]Theory!F29 -> 8 | L15: 5 | M15: 6 | N15: 5 | O15: =[1]Theory!G29 -> 16 | P15: =E15+I15+J15+K15+O15 -> 51 | Q15: =[1]Theory!J29 -> C | S15: =E15+F15+L15 -> 13 | T15: =G15+H15+K15+M15 -> 24 | U15: =J15+N15 -> 14 | V15: =((S15/$S$7)*100) -> 23.214286 | W15: =((T15/$T$7)*100) -> 54.545455 | X15: =((U15/$U$7)*100) -> 53.846154 | Y15: =IF(V15>=50,"Y","N") -> N | Z15: =IF(W15>=50,"Y","N") -> Y | AA15: =IF(X15>=50,"Y","N") -> Y
B16: 6 | C16: =[1]Theory!A30 -> 2023-IT-06 | D16: =[1]Theory!B30 -> Mehak Asghar | E16: =[1]Theory!D30 -> 10 | F16: 6 | G16: 10 | H16: 10 | I16: =[1]Theory!E30 -> 26 | J16: =[1]Theory!H30 -> 9 | K16: =[1]Theory!F30 -> 10 | L16: 9 | M16: 10 | N16: 11 | O16: =[1]Theory!G30 -> 30 | P16: =E16+I16+J16+K16+O16 -> 85 | Q16: =[1]Theory!J30 -> A+ | S16: =E16+F16+L16 -> 25 | T16: =G16+H16+K16+M16 -> 40 | U16: =J16+N16 -> 20 | V16: =((S16/$S$7)*100) -> 44.642857 | W16: =((T16/$T$7)*100) -> 90.909091 | X16: =((U16/$U$7)*100) -> 76.923077 | Y16: =IF(V16>=50,"Y","N") -> N | Z16: =IF(W16>=50,"Y","N") -> Y | AA16: =IF(X16>=50,"Y","N") -> Y
B17: 7 | C17: =[1]Theory!A31 -> 2023-IT-07 | D17: =[1]Theory!B31 -> Humaira Afzal | E17: =[1]Theory!D31 -> 7 | F17: 8 | G17: 5 | H17: 7 | I17: =[1]Theory!E31 -> 20 | J17: =[1]Theory!H31 -> 7 | K17: =[1]Theory!F31 -> 7 | L17: 7 | M17: 7 | N17: 7 | O17: =[1]Theory!G31 -> 21 | P17: =E17+I17+J17+K17+O17 -> 62 | Q17: =[1]Theory!J31 -> B | S17: =E17+F17+L17 -> 22 | T17: =G17+H17+K17+M17 -> 26 | U17: =J17+N17 -> 14 | V17: =((S17/$S$7)*100) -> 39.285714 | W17: =((T17/$T$7)*100) -> 59.090909 | X17: =((U17/$U$7)*100) -> 53.846154 | Y17: =IF(V17>=50,"Y","N") -> N | Z17: =IF(W17>=50,"Y","N") -> Y | AA17: =IF(X17>=50,"Y","N") -> Y
B18: 8 | C18: =[1]Theory!A32 -> 2023-IT-08 | D18: =[1]Theory!B32 -> Saleena Khan | E18: =[1]Theory!D32 -> 0 | F18: 0 | G18: 0 | H18: 0 | I18: =[1]Theory!E32 -> 0 | J18: =[1]Theory!H32 -> 0 | K18: =[1]Theory!F32 -> 0 | L18: 0 | M18: 0 | N18: 0 | O18: =[1]Theory!G32 -> 0 | P18: =E18+I18+J18+K18+O18 -> 0 | Q18: =[1]Theory!J32 -> F | S18: =E18+F18+L18 -> 0 | T18: =G18+H18+K18+M18 -> 0 | U18: =J18+N18 -> 0 | V18: =((S18/$S$7)*100) -> 0 | W18: =((T18/$T$7)*100) -> 0 | X18: =((U18/$U$7)*100) -> 0 | Y18: =IF(V18>=50,"Y","N") -> N | Z18: =IF(W18>=50,"Y","N") -> N | AA18: =IF(X18>=50,"Y","N") -> N
B19: 9 | C19: =[1]Theory!A33 -> 2023-IT-10 | D19: =[1]Theory!B33 -> Asad Ullah | E19: =[1]Theory!D33 -> 10 | F19: 2 | G19: 5 | H19: 6 | I19: =[1]Theory!E33 -> 13 | J19: =[1]Theory!H33 -> 9 | K19: =[1]Theory!F33 -> 9 | L19: 8 | M19: 6 | N19: 5 | O19: =[1]Theory!G33 -> 19 | P19: =E19+I19+J19+K19+O19 -> 60 | Q19: =[1]Theory!J33 -> B | S19: =E19+F19+L19 -> 20 | T19: =G19+H19+K19+M19 -> 26 | U19: =J19+N19 -> 14 | V19: =((S19/$S$7)*100) -> 35.714286 | W19: =((T19/$T$7)*100) -> 59.090909 | X19: =((U19/$U$7)*100) -> 53.846154 | Y19: =IF(V19>=50,"Y","N") -> N | Z19: =IF(W19>=50,"Y","N") -> Y | AA19: =IF(X19>=50,"Y","N") -> Y
B20: 10 | C20: =[1]Theory!A34 -> 2023-IT-11 | D20: =[1]Theory!B34 -> Rana Talha dawood | E20: =[1]Theory!D34 -> 6 | F20: 5 | G20: 6 | H20: 7 | I20: =[1]Theory!E34 -> 18 | J20: =[1]Theory!H34 -> 6 | K20: =[1]Theory!F34 -> 6 | L20: 7 | M20: 5 | N20: 5 | O20: =[1]Theory!G34 -> 17 | P20: =E20+I20+J20+K20+O20 -> 53 | Q20: =[1]Theory!J34 -> C+ | S20: =E20+F20+L20 -> 18 | T20: =G20+H20+K20+M20 -> 24 | U20: =J20+N20 -> 11 | V20: =((S20/$S$7)*100) -> 32.142857 | W20: =((T20/$T$7)*100) -> 54.545455 | X20: =((U20/$U$7)*100) -> 42.307692 | Y20: =IF(V20>=50,"Y","N") -> N | Z20: =IF(W20>=50,"Y","N") -> Y | AA20: =IF(X20>=50,"Y","N") -> N
B21: 11 | C21: =[1]Theory!A35 -> 2023-IT-12 | D21: =[1]Theory!B35 -> Ali Ahmad | E21: =[1]Theory!D35 -> 8 | F21: 5 | G21: 5 | H21: 4 | I21: =[1]Theory!E35 -> 14 | J21: =[1]Theory!H35 -> 8 | K21: =[1]Theory!F35 -> 7 | L21: 8 | M21: 8 | N21: 7 | O21: =[1]Theory!G35 -> 23 | P21: =E21+I21+J21+K21+O21 -> 60 | Q21: =[1]Theory!J35 -> B | S21: =E21+F21+L21 -> 21 | T21: =G21+H21+K21+M21 -> 24 | U21: =J21+N21 -> 15 | V21: =((S21/$S$7)*100) -> 37.5 | W21: =((T21/$T$7)*100) -> 54.545455 | X21: =((U21/$U$7)*100) -> 57.692308 | Y21: =IF(V21>=50,"Y","N") -> N | Z21: =IF(W21>=50,"Y","N") -> Y | AA21: =IF(X21>=50,"Y","N") -> Y
B22: 12 | C22: =[1]Theory!A36 -> 2023-IT-13 | D22: =[1]Theory!B36 -> Muhammad Daud | E22: =[1]Theory!D36 -> 8 | F22: 8 | G22: 8 | H22: 8 | I22: =[1]Theory!E36 -> 24 | J22: =[1]Theory!H36 -> 9 | K22: =[1]Theory!F36 -> 8 | L22: 7 | M22: 7 | N22: 8 | O22: =[1]Theory!G36 -> 22 | P22: =E22+I22+J22+K22+O22 -> 71 | Q22: =[1]Theory!J36 -> A- | S22: =E22+F22+L22 -> 23 | T22: =G22+H22+K22+M22 -> 31 | U22: =J22+N22 -> 17 | V22: =((S22/$S$7)*100) -> 41.071429 | W22: =((T22/$T$7)*100) -> 70.454545 | X22: =((U22/$U$7)*100) -> 65.384615 | Y22: =IF(V22>=50,"Y","N") -> N | Z22: =IF(W22>=50,"Y","N") -> Y | AA22: =IF(X22>=50,"Y","N") -> Y
... B54: 44 | C54: =[1]Theory!A68 -> 2023-IT-80 | D54: =[1]Theory!B68 -> Ali Raza | E54: =[1]Theory!D68 -> 8 | F54: 8 | G54: 5 | H54: 7 | I54: =[1]Theory!E68 -> 20 | J54: =[1]Theory!H68 -> 9 | K54: =[1]Theory!F68 -> 9 | L54: 6 | M54: 5 | N54: 6 | O54: =[1]Theory!G68 -> 17 | P54: =E54+I54+J54+K54+O54 -> 63 | Q54: =[1]Theory!J68 -> B | S54: =E54+F54+L54 -> 22 | T54: =G54+H54+K54+M54 -> 26 | U54: =J54+N54 -> 15 | V54: =((S54/$S$7)*100) -> 39.285714 | W54: =((T54/$T$7)*100) -> 59.090909 | X54: =((U54/$U$7)*100) -> 57.692308 | Y54: =IF(V54>=50,"Y","N") -> N | Z54: =IF(W54>=50,"Y","N") -> Y | AA54: =IF(X54>=50,"Y","N") -> Y
B56: Teacher Incharge Signature | F56: Incharge Department Signature
B57: Engr. M Talha Jahangir | F57: (Engr. M. Kashan Basit)
B61: =B1 -> MNS - UNIVERSITY OF ENGINEERING AND TECHNOLOGY MULTAN
B62: =E3 -> Title (Code): Programming Fundamental (IT-111) | D62: =S1 -> Fall 2023
D63: =X1 -> Engr. M Talha Jahangir
B64: Activity Sheet Statistics
D67: No. of Students
B68: Sr. No. | C68: PLO | D68: Achieved the PLO | F68: Not Achieved the PLO
B69: 1 | C69: =S6 -> 2 | D69: =COUNTIF($Y$11:$Y$54,Y10) -> 0 | F69: =COUNTIF($Y$11:$Y$54,Z10) -> 44
B70: 2 | C70: =T6 -> 2 | D70: =COUNTIF($Z$11:$Z$54,Z11) -> 36 | F70: =COUNTIF($Z$11:$Z$54,Z10) -> 8
B71: 3 | C71: =U6 -> 4 | D71: =COUNTIF($AA$11:$AA$54,Y10) -> 35 | F71: =COUNTIF($AA$11:$AA$54,Z10) -> 9
C100: Cohert Failure =

Sheet Discrete Structure
B1: =[2]Theory!A1 -> MNS - UNIVERSITY OF ENGINEERING AND TECHNOLOGY MULTAN | L1: =[2]Theory!B4 -> Fall-2023-2027 (Evening-A) | P1: =[2]Theory!H3 -> 1st Semester | S1: =[2]Theory!H4 -> Fall 2023 | W1: =[2]Theory!H5 -> Zain ul abdeen
B2: Activity Sheet | I2: =[2]Theory!B3 -> BS Information Technology | R2: CLO & PLO Assessment
B3: Subject: | E3: =[2]Theory!B5 -> Title (Code): Discrete Structure (IT-113
B4: Component Name | E4: Quiz 1 | F4: Mid Term | J4: C.P | K4: Quiz 2 | L4: Final Term | P4: Total | Q4: Grade | R4: CLOs vs. PLOs
B5: Total Marks | E5: 10 | F5: 30 | J5: 10 | K5: 10 | L5: 16 | M5: 14 | N5: 10 | O5: 40 | P5: =SUM(E5:N5) -> 100 | R5: CLOs | S5: 2 | T5: 3 | U5: 4
B6: Question Components | E6: Q 1 | F6: Q1 | G6: Q2 | H6: Q3 | I6: Total | J6: Q1 | K6: Q1 | L6: Q1 | M6: Q2 | N6: Q3 | O6: Total | R6: PLOs | S6: 2 | T6: 2 | U6: 3
B7: Component Marks | E7: 10 | F7: 10 | G7: 10 | H7: 10 | I7: =F7+G7+H7 -> 30 | J7: 10 | K7: 10 | L7: 10 | M7: 14 | N7: 16 | O7: 40 | P7: =SUM(E7:H7,J7:N7) -> 100 | S7: 44 | T7: 26 | U7: 30
D8: KPI | E8: =E7*0.5 -> 5 | F8: =F7*0.5 -> 5 | G8: =G7*0.5 -> 5 | H8: =H7*0.5 -> 5 | I8: =I7*0.5 -> 15 | J8: =J7*0.5 -> 5 | K8: =K7*0.5 -> 5 | L8: =L7*0.5 -> 5 | ... O8: =O7*0.5 -> 20 | P8: =SUM(E8:H8)+SUM(J8:J8)+SUM(K8:N8) -> 50 | S8: Assessment of CLOs | V8: PLOs Acheivement | X8: PLOs Acheivement
D9: CLO Mapping | E9: 4 | F9: 4 | G9: 2 | H9: 2 | J9: 3 | K9: 2 | L9: 4 | M9: 2 | N9: 3 | S9: =S5 -> 2 | T9: =T5 -> 3 | U9: =U5 -> 4 | V9: =S6 -> 2 | W9: =U6 -> 3 | X9: =S6 -> 2 | Y9: =U6 -> 3
B10: Sr. No. | C10: Registration No. | D10: Student Name | X10: Y | Y10: N
B11: 1 | C11: =[2]Theory!A25 -> 2023-IT-09 | D11: =[2]Theory!B25 -> Mahad Elahi | E11: =[2]Theory!D25 -> 7 | F11: 7 | G11: 7 | H11: 6 | I11: =[2]Theory!E25 -> 20 | J11: =[2]Theory!H25 -> 7 | K11: =[2]Theory!F25 -> 7 | L11: 7 | M11: 14 | N11: 13 | O11: =[2]Theory!G25 -> 34 | P11: =E11+I11+J11+K11+O11 -> 75 | Q11: =[2]Theory!J25 -> B | S11: =G11+H11+K11+M11 -> 34 | T11: =J11+N11 -> 20 | U11: =E11+F11+L11 -> 21 | V11: =(((S11+T11)/($S$7+$T$7))*100) -> 77.142857 | W11: =((U11/$U$7)*100) -> 70 | X11: =IF(V11>=50,"Y","N") -> Y | Y11: =IF(W11>=50,"Y","N") -> Y
B12: 2 | C12: =[2]Theory!A26 -> 2023-IT-15 | D12: =[2]Theory!B26 -> Muhammad Faraz Shabbir | E12: =[2]Theory!D26 -> 0 | F12: 0 | G12: 0 | H12: 0 | I12: =[2]Theory!E26 -> 0 | J12: =[2]Theory!H26 -> 0 | K12: =[2]Theory!F26 -> 0 | L12: 0 | M12: 0 | N12: 0 | O12: =[2]Theory!G26 -> 0 | P12: =E12+I12+J12+K12+O12 -> 0 | Q12: =[2]Theory!J26 -> F | S12: =G12+H12+K12+M12 -> 0 | T12: =J12+N12 -> 0 | U12: =E12+F12+L12 -> 0 | V12: =(((S12+T12)/($S$7+$T$7))*100) -> 0 | W12: =((U12/$U$7)*100) -> 0 | X12: =IF(V12>=50,"Y","N") -> N | Y12: =IF(W12>=50,"Y","N") -> N
B13: 3 | C13: =[2]Theory!A27 -> 2023-IT-17 | D13: =[2]Theory!B27 -> Muhammad Bilal Imtiaz | E13: =[2]Theory!D27 -> 7 | F13: 8 | G13: 7 | H13: 10 | I13: =[2]Theory!E27 -> 25 | J13: =[2]Theory!H27 -> 7 | K13: =[2]Theory!F27 -> 8 | L13: 8 | M13: 14 | N13: 16 | O13: =[2]Theory!G27 -> 38 | P13: =E13+I13+J13+K13+O13 -> 85 | Q13: =[2]Theory!J27 -> A- | S13: =G13+H13+K13+M13 -> 39 | T13: =J13+N13 -> 23 | U13: =E13+F13+L13 -> 23 | V13: =(((S13+T13)/($S$7+$T$7))*100) -> 88.571429 | W13: =((U13/$U$7)*100) -> 76.666667 | X13: =IF(V13>=50,"Y","N") -> Y | Y13: =IF(W13>=50,"Y","N") -> Y
B14: 4 | C14: =[2]Theory!A28 -> 2023-IT-19 | D14: =[2]Theory!B28 -> Abdul Basit | E14: =[2]Theory!D28 -> 8 | F14: 10 | G14: 7 | H14: 8 | I14: =[2]Theory!E28 -> 25 | J14: =[2]Theory!H28 -> 9 | K14: =[2]Theory!F28 -> 7 | L14: 9 | M14: 13 | N14: 16 | O14: =[2]Theory!G28 -> 38 | P14: =E14+I14+J14+K14+O14 -> 87 | Q14: =[2]Theory!J28 -> A- | S14: =G14+H14+K14+M14 -> 35 | T14: =J14+N14 -> 25 | U14: =E14+F14+L14 -> 27 | V14: =(((S14+T14)/($S$7+$T$7))*100) -> 85.714286 | W14: =((U14/$U$7)*100) -> 90 | X14: =IF(V14>=50,"Y","N") -> Y | Y14: =IF(W14>=50,"Y","N") -> Y
B15: 5 | C15: =[2]Theory!A29 -> 2023-IT-21 | D15: =[2]Theory!B29 -> Zain Jameel | E15: =[2]Theory!D29 -> 7 | F15: 10 | G15: 9 | H15: 6 | I15: =[2]Theory!E29 -> 25 | J15: =[2]Theory!H29 -> 8 | K15: =[2]Theory!F29 -> 8 | L15: 8 | M15: 12 | N15: 14 | O15: =[2]Theory!G29 -> 34 | P15: =E15+I15+J15+K15+O15 -> 82 | Q15: =[2]Theory!J29 -> B+ | S15: =G15+H15+K15+M15 -> 35 | T15: =J15+N15 -> 22 | U15: =E15+F15+L15 -> 25 | V15: =(((S15+T15)/($S$7+$T$7))*100) -> 81.428571 | W15: =((U15/$U$7)*100) -> 83.333333 | X15: =IF(V15>=50,"Y","N") -> Y | Y15: =IF(W15>=50,"Y","N") -> Y
B16: 6 | C16: =[2]Theory!A30 -> 2023-IT-23 | D16: =[2]Theory!B30 -> Hafiz Haseeb Ur Rehman | E16: =[2]Theory!D30 -> 7 | F16: 8 | G16: 6 | H16: 8 | I16: =[2]Theory!E30 -> 22 | J16: =[2]Theory!H30 -> 6 | K16: =[2]Theory!F30 -> 7 | L16: 10 | M16: 12 | N16: 11 | O16: =[2]Theory!G30 -> 33 | P16: =E16+I16+J16+K16+O16 -> 75 | Q16: =[2]Theory!J30 -> B | S16: =G16+H16+K16+M16 -> 33 | T16: =J16+N16 -> 17 | U16: =E16+F16+L16 -> 25 | V16: =(((S16+T16)/($S$7+$T$7))*100) -> 71.428571 | W16: =((U16/$U$7)*100) -> 83.333333 | X16: =IF(V16>=50,"Y","N") -> Y | Y16: =IF(W16>=50,"Y","N") -> Y
B17: 7 | C17: =[2]Theory!A31 -> 2023-IT-25 | D17: =[2]Theory!B31 -> Muhammad Muzammil | E17: =[2]Theory!D31 -> 7 | F17: 7 | G17: 5 | H17: 5 | I17: =[2]Theory!E31 -> 17 | J17: =[2]Theory!H31 -> 7 | K17: =[2]Theory!F31 -> 7 | L17: 8 | M17: 10 | N17: 12 | O17: =[2]Theory!G31 -> 30 | P17: =E17+I17+J17+K17+O17 -> 68 | Q17: =[2]Theory!J31 -> C+ | S17: =G17+H17+K17+M17 -> 27 | T17: =J17+N17 -> 19 | U17: =E17+F17+L17 -> 22 | V17: =(((S17+T17)/($S$7+$T$7))*100) -> 65.714286 | W17: =((U17/$U$7)*100) -> 73.333333 | X17: =IF(V17>=50,"Y","N") -> Y | Y17: =IF(W17>=50,"Y","N") -> Y
B18: 8 | C18: =[2]Theory!A32 -> 2023-IT-27 | D18: =[2]Theory!B32 -> Talha Irfan | E18: =[2]Theory!D32 -> 8 | F18: 10 | G18: 7 | H18: 10 | I18: =[2]Theory!E32 -> 27 | J18: =[2]Theory!H32 -> 8 | K18: =[2]Theory!F32 -> 9 | L18: 10 | M18: 13 | N18: 16 | O18: =[2]Theory!G32 -> 39 | P18: =E18+I18+J18+K18+O18 -> 91 | Q18: =[2]Theory!J32 -> A | S18: =G18+H18+K18+M18 -> 39 | T18: =J18+N18 -> 24 | U18: =E18+F18+L18 -> 28 | V18: =(((S18+T18)/($S$7+$T$7))*100) -> 90 | W18: =((U18/$U$7)*100) -> 93.333333 | X18: =IF(V18>=50,"Y","N") -> Y | Y18: =IF(W18>=50,"Y","N") -> Y
B19: 9 | C19: =[2]Theory!A33 -> 2023-IT-29 | D19: =[2]Theory!B33 -> Husnain Abbas | E19: =[2]Theory!D33 -> 8 | F19: 8 | G19: 8 | H19: 2 | I19: =[2]Theory!E33 -> 18 | J19: =[2]Theory!H33 -> 8 | K19: =[2]Theory!F33 -> 8 | L19: 10 | M19: 10 | N19: 14 | O19: =[2]Theory!G33 -> 34 | P19: =E19+I19+J19+K19+O19 -> 76 | Q19: =[2]Theory!J33 -> B | S19: =G19+H19+K19+M19 -> 28 | T19: =J19+N19 -> 22 | U19: =E19+F19+L19 -> 26 | V19: =(((S19+T19)/($S$7+$T$7))*100) -> 71.428571 | W19: =((U19/$U$7)*100) -> 86.666667 | X19: =IF(V19>=50,"Y","N") -> Y | Y19: =IF(W19>=50,"Y","N") -> Y
B20: 10 | C20: =[2]Theory!A34 -> 2023-IT-30 | D20: =[2]Theory!B34 -> Umair Ahmad | E20: =[2]Theory!D34 -> 8 | F20: 6 | G20: 5 | H20: 3 | I20: =[2]Theory!E34 -> 14 | J20: =[2]Theory!H34 -> 8 | K20: =[2]Theory!F34 -> 8 | L20: 8 | M20: 10 | N20: 14 | O20: =[2]Theory!G34 -> 32 | P20: =E20+I20+J20+K20+O20 -> 70 | Q20: =[2]Theory!J34 -> B- | S20: =G20+H20+K20+M20 -> 26 | T20: =J20+N20 -> 22 | U20: =E20+F20+L20 -> 22 | V20: =(((S20+T20)/($S$7+$T$7))*100) -> 68.571429 | W20: =((U20/$U$7)*100) -> 73.333333 | X20: =IF(V20>=50,"Y","N") -> Y | Y20: =IF(W20>=50,"Y","N") -> Y
B21: 11 | C21: =[2]Theory!A35 -> 2023-IT-31 | D21: =[2]Theory!B35 -> Muhammad Talha Munir | E21: =[2]Theory!D35 -> 6 | F21: 8 | G21: 8 | H21: 8 | I21: =[2]Theory!E35 -> 24 | J21: =[2]Theory!H35 -> 6 | K21: =[2]Theory!F35 -> 7 | L21: 10 | M21: 10 | N21: 12 | O21: =[2]Theory!G35 -> 32 | P21: =E21+I21+J21+K21+O21 -> 75 | Q21: =[2]Theory!J35 -> B | S21: =G21+H21+K21+M21 -> 33 | T21: =J21+N21 -> 18 | U21: =E21+F21+L21 -> 24 | V21: =(((S21+T21)/($S$7+$T$7))*100) -> 72.857143 | W21: =((U21/$U$7)*100) -> 80 | X21: =IF(V21>=50,"Y","N") -> Y | Y21: =IF(W21>=50,"Y","N") -> Y
B22: 12 | C22: =[2]Theory!A36 -> 2023-IT-33 | D22: =[2]Theory!B36 -> Muhammad Saleem | E22: =[2]Theory!D36 -> 8 | F22: 10 | G22: 7 | H22: 3 | I22: =[2]Theory!E36 -> 20 | J22: =[2]Theory!H36 -> 8 | K22: =[2]Theory!F36 -> 9 | L22: 5 | M22: 9 | N22: 11 | O22: =[2]Theory!G36 -> 25 | P22: =E22+I22+J22+K22+O22 -> 70 | Q22: =[2]Theory!J36 -> B- | S22: =G22+H22+K22+M22 -> 28 | T22: =J22+N22 -> 19 | U22: =E22+F22+L22 -> 23 | V22: =(((S22+T22)/($S$7+$T$7))*100) -> 67.142857 | W22: =((U22/$U$7)*100) -> 76.666667 | X22: =IF(V22>=50,"Y","N") -> Y | Y22: =IF(W22>=50,"Y","N") -> Y
... B47: 37 | C47: =[2]Theory!A61 -> 2023-IT-82 | D47: =[2]Theory!B61 -> Muhammad Umer | E47: =[2]Theory!D61 -> 8 | F47: 10 | G47: 6 | H47: 7 | I47: =[2]Theory!E61 -> 23 | J47: =[2]Theory!H61 -> 8 | K47: =[2]Theory!F61 -> 7 | L47: 10 | M47: 12 | N47: 16 | O47: =[2]Theory!G61 -> 38 | P47: =E47+I47+J47+K47+O47 -> 84 | Q47: =[2]Theory!J61 -> B+ | S47: =G47+H47+K47+M47 -> 32 | T47: =J47+N47 -> 24 | U47: =E47+F47+L47 -> 28 | V47: =(((S47+T47)/($S$7+$T$7))*100) -> 80 | W47: =((U47/$U$7)*100) -> 93.333333 | X47: =IF(V47>=50,"Y","N") -> Y | Y47: =IF(W47>=50,"Y","N") -> Y
B48: 38
B49: 39
B50: 40
B51: 41
B52: 42
B53: 43
B54: 44
B57: Teacher Incharge Signature
B58: =D64 -> Zain ul abdeen | F58: (Engr. M. Kashan Basit)
B62: =B1 -> MNS - UNIVERSITY OF ENGINEERING AND TECHNOLOGY MULTAN
B63: =E3 -> Title (Code): Discrete Structure (IT-113 | D63: =S1 -> Fall 2023
D64: =W1 -> Zain ul abdeen
B65: Activity Sheet Statistics
D68: No. of Students
B69: Sr. No. | C69: PLO | D69: Achieved the PLO | F69: Not Achieved the PLO
B70: 1 | C70: =S6 -> 2 | D70: =COUNTIF($X$11:$X$55,X10) -> 30 | F70: =COUNTIF($X$11:$X$55,Y10) -> 7
B71: 3 | C71: =U6 -> 3 | D71: =COUNTIF($Y$11:$Y$55,X10) -> 33 | F71: =COUNTIF($Y$11:$Y$55,Y10) -> 4
...

Sheet Calculus and Analytic Geometry
B1: =[3]Theory!A1 -> MNS - UNIVERSITY OF ENGINEERING AND TECHNOLOGY MULTAN | L1: =[3]Theory!B4 -> Fall-2023-2027 (Evening-A) | P1: =[3]Theory!H3 -> 1st Semester | S1: =[3]Theory!H4 -> Fall 2023 | X1: =[3]Theory!H5 -> Muhammad Aamir
B2: Activity Sheet | I2: =[3]Theory!B3 -> BS Information Technology | R2: CLO & PLO Assessment
B3: Subject: | E3: =[3]Theory!B5 -> Title (Code): Calculus and Analytical Geometry (MTH-114)
B4: Component Name | E4: Quiz 1 | F4: Mid Term | J4: C.P | K4: Quiz 2 | L4: Final Term | P4: Total | Q4: Grade | R4: CLOs vs. PLOs
B5: Total Marks | E5: 10 | F5: 30 | J5: 10 | K5: 10 | L5: 16 | M5: 14 | N5: 10 | O5: 40 | P5: =SUM(E5:N5) -> 100 | R5: CLOs | S5: 1 | T5: 2
B6: Question Components | E6: Q 1 | F6: Q1 | G6: Q2 | H6: Q3 | I6: Total | J6: Q1 | K6: Q1 | L6: Q1 | M6: Q2 | N6: Q3 | O6: Total | R6: PLOs | S6: 2 | T6: 3
B7: Component Marks | E7: 10 | F7: 10 | G7: 10 | H7: 10 | I7: =F7+G7+H7 -> 30 | J7: 10 | K7: 10 | L7: 10 | M7: 14 | N7: 16 | O7: 40 | P7: =SUM(E7:H7,J7:N7) -> 100 | S7: 56 | T7: =G7+H7+K7+M7 -> 44
D8: KPI | E8: =E7*0.5 -> 5 | F8: =F7*0.5 -> 5 | G8: =G7*0.5 -> 5 | H8: =H7*0.5 -> 5 | I8: =I7*0.5 -> 15 | J8: =J7*0.5 -> 5 | K8: =K7*0.5 -> 5 | L8: =L7*0.5 -> 5 | ... O8: =O7*0.5 -> 20 | P8: =SUM(E8:H8)+SUM(J8:J8)+SUM(K8:N8) -> 50 | S8: Assessment of CLOs | V8: PLOs Acheivement | Y8: PLOs Acheivement
D9: CLO Mapping | E9: 1 | F9: 1 | G9: 2 | H9: 2 | J9: 1 | K9: 2 | L9: 1 | M9: 2 | N9: 1 | S9: =S5 -> 1 | T9: =T5 -> 2 | U9: 3 | V9: 2 | W9: 3 | Y9: =S6 -> 2 | Z9: =T6 -> 3
B10: Sr. No. | C10: Registration No. | D10: Student Name | Y10: Y | Z10: N
B11: 1 | C11: =[3]Theory!A25 -> 2023-IT-01 | D11: =[3]Theory!B25 -> Rahma Noor | E11: =[3]Theory!D25 -> 3 | F11: 10 | G11: 6 | H11: 8 | I11: =[3]Theory!E25 -> 24 | J11: =[3]Theory!H25 -> 10 | K11: =[3]Theory!F25 -> 8 | L11: 5 | M11: 12 | N11: 14 | O11: =[3]Theory!G25 -> 31 | P11: =E11+I11+J11+K11+O11 -> 76 | Q11: =[3]Theory!J25 -> A- | S11: =E11+F11+L11+J11+N11 -> 42 | T11: =G11+H11+K11+M11 -> 34 | V11: =((S11/$S$7)*100) -> 75 | W11: =((T11/$T$7)*100) -> 77.272727 | Y11: =IF(V11>=50,"Y","N") -> Y | Z11: =IF(W11>=50,"Y","N") -> Y
B12: 2 | C12: =[3]Theory!A26 -> 2023-IT-02 | D12: =[3]Theory!B26 -> Alishba Manzoor | E12: =[3]Theory!D26 -> 8 | F12: 8 | G12: 5 | H12: 6 | I12: =[3]Theory!E26 -> 19 | J12: =[3]Theory!H26 -> 10 | K12: =[3]Theory!F26 -> 8 | L12: 3 | M12: 4 | N12: 7 | O12: =[3]Theory!G26 -> 14 | P12: =E12+I12+J12+K12+O12 -> 59 | Q12: =[3]Theory!J26 -> B | S12: =E12+F12+L12+J12+N12 -> 36 | T12: =G12+H12+K12+M12 -> 23 | V12: =((S12/$S$7)*100) -> 64.285714 | W12: =((T12/$T$7)*100) -> 52.272727 | Y12: =IF(V12>=50,"Y","N") -> Y | Z12: =IF(W12>=50,"Y","N") -> Y
B13: 3 | C13: =[3]Theory!A27 -> 2023-IT-03 | D13: =[3]Theory!B27 -> Maheen Fatima | E13: =[3]Theory!D27 -> 6 | F13: 8 | G13: 8 | H13: 7 | I13: =[3]Theory!E27 -> 23 | J13: =[3]Theory!H27 -> 8 | K13: =[3]Theory!F27 -> 8 | L13: 4 | M13: 8 | N13: 6 | O13: =[3]Theory!G27 -> 18 | P13: =E13+I13+J13+K13+O13 -> 63 | Q13: =[3]Theory!J27 -> B+ | S13: =E13+F13+L13+J13+N13 -> 32 | T13: =G13+H13+K13+M13 -> 31 | V13: =((S13/$S$7)*100) -> 57.142857 | W13: =((T13/$T$7)*100) -> 70.454545 | Y13: =IF(V13>=50,"Y","N") -> Y | Z13: =IF(W13>=50,"Y","N") -> Y
B14: 4 | C14: =[3]Theory!A28 -> 2023-IT-04 | D14: =[3]Theory!B28 -> Aneela | E14: =[3]Theory!D28 -> 6 | F14: 8 | G14: 6 | H14: 7 | I14: =[3]Theory!E28 -> 22 | J14: =[3]Theory!H28 -> 8 | K14: =[3]Theory!F28 -> 0 | L14: 3 | M14: 11 | N14: 8 | O14: =[3]Theory!G28 -> 22 | P14: =E14+I14+J14+K14+O14 -> 58 | Q14: =[3]Theory!J28 -> B | S14: =E14+F14+L14+J14+N14 -> 33 | T14: =G14+H14+K14+M14 -> 24 | V14: =((S14/$S$7)*100) -> 58.928571 | W14: =((T14/$T$7)*100) -> 54.545455 | Y14: =IF(V14>=50,"Y","N") -> Y | Z14: =IF(W14>=50,"Y","N") -> Y
B15: 5 | C15: =[3]Theory!A29 -> 2023-IT-05 | D15: =[3]Theory!B29 -> Alishba Saleem | E15: =[3]Theory!D29 -> 3 | F15: 10 | G15: 5 | H15: 6 | I15: =[3]Theory!E29 -> 21 | J15: =[3]Theory!H29 -> 8 | K15: =[3]Theory!F29 -> 9 | L15: 5 | M15: 8 | N15: 10 | O15: =[3]Theory!G29 -> 23 | P15: =E15+I15+J15+K15+O15 -> 64 | Q15: =[3]Theory!J29 -> B+ | S15: =E15+F15+L15+J15+N15 -> 36 | T15: =G15+H15+K15+M15 -> 28 | V15: =((S15/$S$7)*100) -> 64.285714 | W15: =((T15/$T$7)*100) -> 63.636364 | Y15: =IF(V15>=50,"Y","N") -> Y | Z15: =IF(W15>=50,"Y","N") -> Y
B16: 6 | C16: =[3]Theory!A30 -> 2023-IT-06 | D16: =[3]Theory!B30 -> Mehak Asghar | E16: =[3]Theory!D30 -> 10 | F16: 7 | G16: 10 | H16: 10 | I16: =[3]Theory!E30 -> 27 | J16: =[3]Theory!H30 -> 8 | K16: =[3]Theory!F30 -> 9 | L16: 5 | M16: 10 | N16: 15 | O16: =[3]Theory!G30 -> 30 | P16: =E16+I16+J16+K16+O16 -> 84 | Q16: =[3]Theory!J30 -> A | S16: =E16+F16+L16+J16+N16 -> 45 | T16: =G16+H16+K16+M16 -> 39 | V16: =((S16/$S$7)*100) -> 80.357143 | W16: =((T16/$T$7)*100) -> 88.636364 | Y16: =IF(V16>=50,"Y","N") -> Y | Z16: =IF(W16>=50,"Y","N") -> Y
B17: 7 | C17: =[3]Theory!A31 -> 2023-IT-07 | D17: =[3]Theory!B31 -> Humaira Afzal | E17: =[3]Theory!D31 -> 4 | F17: 10 | G17: 6 | H17: 6 | I17: =[3]Theory!E31 -> 22 | J17: =[3]Theory!H31 -> 8 | K17: =[3]Theory!F31 -> 9 | L17: 5 | M17: 8 | N17: 10 | O17: =[3]Theory!G31 -> 23 | P17: =E17+I17+J17+K17+O17 -> 66 | Q17: =[3]Theory!J31 -> B+ | S17: =E17+F17+L17+J17+N17 -> 37 | T17: =G17+H17+K17+M17 -> 29 | V17: =((S17/$S$7)*100) -> 66.071429 | W17: =((T17/$T$7)*100) -> 65.909091 | Y17: =IF(V17>=50,"Y","N") -> Y | Z17: =IF(W17>=50,"Y","N") -> Y
B18: 8 | C18: =[3]Theory!A32 -> 2023-IT-08 | D18: =[3]Theory!B32 -> Saleena Khan | E18: =[3]Theory!D32 -> 0 | F18: 0 | G18: 0 | H18: 0 | I18: =[3]Theory!E32 -> 0 | J18: =[3]Theory!H32 -> 0 | K18: =[3]Theory!F32 -> 0 | L18: 0 | M18: 0 | N18: 0 | O18: =[3]Theory!G32 -> 0 | P18: =E18+I18+J18+K18+O18 -> 0 | Q18: =[3]Theory!J32 -> F | S18: =E18+F18+L18+J18+N18 -> 0 | T18: =G18+H18+K18+M18 -> 0 | V18: =((S18/$S$7)*100) -> 0 | W18: =((T18/$T$7)*100) -> 0 | Y18: =IF(V18>=50,"Y","N") -> N | Z18: =IF(W18>=50,"Y","N") -> N
B19: 9 | C19: =[3]Theory!A33 -> 2023-IT-10 | D19: =[3]Theory!B33 -> Asad Ullah | E19: =[3]Theory!D33 -> 4 | F19: 4 | G19: 2 | H19: 1 | I19: =[3]Theory!E33 -> 7 | J19: =[3]Theory!H33 -> 9 | K19: =[3]Theory!F33 -> 6 | L19: 7 | M19: 2 | N19: 0 | O19: =[3]Theory!G33 -> 9 | P19: =E19+I19+J19+K19+O19 -> 35 | Q19: =[3]Theory!J33 -> D | S19: =E19+F19+L19+J19+N19 -> 24 | T19: =G19+H19+K19+M19 -> 11 | V19: =((S19/$S$7)*100) -> 42.857143 | W19: =((T19/$T$7)*100) -> 25 | Y19: =IF(V19>=50,"Y","N") -> N | Z19: =IF(W19>=50,"Y","N") -> N
B20: 10 | C20: =[3]Theory!A34 -> 2023-IT-11 | D20: =[3]Theory!B34 -> Rana Talha dawood | E20: =[3]Theory!D34 -> 6 | F20: 4 | G20: 4 | H20: 3 | I20: =[3]Theory!E34 -> 11 | J20: =[3]Theory!H34 -> 8 | K20: =[3]Theory!F34 -> 8 | L20: 7 | M20: 10 | N20: 10 | O20: =[3]Theory!G34 -> 27 | P20: =E20+I20+J20+K20+O20 -> 60 | Q20: =[3]Theory!J34 -> B | S20: =E20+F20+L20+J20+N20 -> 35 | T20: =G20+H20+K20+M20 -> 25 | V20: =((S20/$S$7)*100) -> 62.5 | W20: =((T20/$T$7)*100) -> 56.818182 | Y20: =IF(V20>=50,"Y","N") -> Y | Z20: =IF(W20>=50,"Y","N") -> Y
B21: 11 | C21: =[3]Theory!A35 -> 2023-IT-12 | D21: =[3]Theory!B35 -> Ali Ahmad | E21: =[3]Theory!D35 -> 3 | F21: 8 | G21: 5 | H21: 4 | I21: =[3]Theory!E35 -> 17 | J21: =[3]Theory!H35 -> 7 | K21: =[3]Theory!F35 -> 7 | L21: 4 | M21: 8 | N21: 12 | O21: =[3]Theory!G35 -> 24 | P21: =E21+I21+J21+K21+O21 -> 58 | Q21: =[3]Theory!J35 -> B | S21: =E21+F21+L21+J21+N21 -> 34 | T21: =G21+H21+K21+M21 -> 24 | V21: =((S21/$S$7)*100) -> 60.714286 | W21: =((T21/$T$7)*100) -> 54.545455 | Y21: =IF(V21>=50,"Y","N") -> Y | Z21: =IF(W21>=50,"Y","N") -> Y
B22: 12 | C22: =[3]Theory!A36 -> 2023-IT-13 | D22: =[3]Theory!B36 -> Muhammad Daud | E22: =[3]Theory!D36 -> 7 | F22: 3 | G22: 4 | H22: 3 | I22: =[3]Theory!E36 -> 10 | J22: =[3]Theory!H36 -> 9 | K22: =[3]Theory!F36 -> 7 | L22: 5 | M22: 6 | N22: 2 | O22: =[3]Theory!G36 -> 13 | P22: =E22+I22+J22+K22+O22 -> 46 | Q22: =[3]Theory!J36 -> C | S22: =E22+F22+L22+J22+N22 -> 26 | T22: =G22+H22+K22+M22 -> 20 | V22: =((S22/$S$7)*100) -> 46.428571 | W22: =((T22/$T$7)*100) -> 45.454545 | Y22: =IF(V22>=50,"Y","N") -> N | Z22: =IF(W22>=50,"Y","N") -> N
... B28: 18 | C28: =[3]Theory!A42 -> 2023-IT-24 | D28: =[3]Theory!B42 -> Sher Shah Hussain | E28: =[3]Theory!D42 -> 6 | F28: 9 | G28: 7 | H28: 7 | I28: =[3]Theory!E42 -> 23 | J28: =[3]Theory!H42 -> 8 | K28: =[3]Theory!F42 -> 8 | L28: 4 | M28: 5 | N28: 10 | O28: =[3]Theory!G42 -> 19 | P28: =E28+I28+J28+K28+O28 -> 64 | Q28: =[3]Theory!J42 -> B+ | S28: =E28+F28+L28+J28+N28 -> 37 | T28: =G28+H28+K28+M28 -> 27 | V28: =((S28/$S$7)*100) -> 66.071429 | W28: =((T28/$T$7)*100) -> 61.363636 | Y28: =IF(V28>=50,"Y","N") -> Y | Z28: =IF(W28>=50,"Y","N") -> Y
B29: 19 | C29: =[3]Theory!A43 -> 2023-IT-26 | D29: =[3]Theory!B43 -> Abdul Ahad | E29: =[3]Theory!D43 -> 0 | F29: 0 | G29: 0 | H29: 0 | I29: 0 | J29: =[3]Theory!H43 -> 0 | K29: =[3]Theory!F43 -> 0 | L29: 0 | M29: 0 | N29: 0 | O29: =[3]Theory!G43 -> 0 | P29: =E29+I29+J29+K29+O29 -> 0 | Q29: =[3]Theory!J43 -> F | S29: =E29+F29+L29+J29+N29 -> 0 | T29: =G29+H29+K29+M29 -> 0 | V29: =((S29/$S$7)*100) -> 0 | W29: =((T29/$T$7)*100) -> 0 | Y29: =IF(V29>=50,"Y","N") -> N | Z29: =IF(W29>=50,"Y","N") -> N
B30: 20 | C30: =[3]Theory!A44 -> 2023-IT-28 | D30: =[3]Theory!B44 -> Ahmad Latif | E30: =[3]Theory!D44 -> 3 | F30: 4 | G30: 1 | H30: 1 | I30: =[3]Theory!E44 -> 6 | J30: =[3]Theory!H44 -> 10 | K30: =[3]Theory!F44 -> 9 | L30: 6 | M30: 2 | N30: 0 | O30: =[3]Theory!G44 -> 8 | P30: =E30+I30+J30+K30+O30 -> 36 | Q30: =[3]Theory!J44 -> D | S30: =E30+F30+L30+J30+N30 -> 23 | T30: =G30+H30+K30+M30 -> 13 | V30: =((S30/$S$7)*100) -> 41.071429 | W30: =((T30/$T$7)*100) -> 29.545455 | Y30: =IF(V30>=50,"Y","N") -> N | Z30: =IF(W30>=50,"Y","N") -> N
B31: 21 | C31: =[3]Theory!A45 -> 2023-IT-32 | D31: =[3]Theory!B45 -> Muhammad Faisal | E31: =[3]Theory!D45 -> 6 | F31: 9 | G31: 9 | H31: 5 | I31: =[3]Theory!E45 -> 23 | J31: =[3]Theory!H45 -> 8 | K31: =[3]Theory!F45 -> 8 | L31: 5 | M31: 8 | N31: 10 | O31: =[3]Theory!G45 -> 23 | P31: =E31+I31+J31+K31+O31 -> 68 | Q31: =[3]Theory!J45 -> B+ | S31: =E31+F31+L31+J31+N31 -> 38 | T31: =G31+H31+K31+M31 -> 30 | V31: =((S31/$S$7)*100) -> 67.857143 | W31: =((T31/$T$7)*100) -> 68.181818 | Y31: =IF(V31>=50,"Y","N") -> Y | Z31: =IF(W31>=50,"Y","N") -> Y
B32: 22 | C32: =[3]Theory!A46 -> 2023-IT-34 | D32: =[3]Theory!B46 -> Jamshaid Abbas | E32: =[3]Theory!D46 -> 4 | F32: 3 | G32: 2 | H32: 1 | I32: =[3]Theory!E46 -> 6 | J32: =[3]Theory!H46 -> 10 | K32: =[3]Theory!F46 -> 6 | L32: 8 | M32: 1 | N32: 1 | O32: =[3]Theory!G46 -> 10 | P32: =E32+I32+J32+K32+O32 -> 36 | Q32: =[3]Theory!J46 -> D | S32: =E32+F32+L32+J32+N32 -> 26 | T32: =G32+H32+K32+M32 -> 10 | V32: =((S32/$S$7)*100) -> 46.428571 | W32: =((T32/$T$7)*100) -> 22.727273 | Y32: =IF(V32>=50,"Y","N") -> N | Z32: =IF(W32>=50,"Y","N") -> N
B33: 23 | C33: =[3]Theory!A47 -> 2023-IT-38 | D33: =[3]Theory!B47 -> Sherzaman Bukhari | E33: =[3]Theory!D47 -> 5 | F33: 7 | G33: 3 | H33: 6 | I33: =[3]Theory!E47 -> 16 | J33: =[3]Theory!H47 -> 8 | K33: =[3]Theory!F47 -> 8 | L33: 6 | M33: 8 | N33: 10 | O33: =[3]Theory!G47 -> 24 | P33: =E33+I33+J33+K33+O33 -> 61 | Q33: =[3]Theory!J47 -> B | S33: =E33+F33+L33+J33+N33 -> 36 | T33: =G33+H33+K33+M33 -> 25 | V33: =((S33/$S$7)*100) -> 64.285714 | W33: =((T33/$T$7)*100) -> 56.818182 | Y33: =IF(V33>=50,"Y","N") -> Y | Z33: =IF(W33>=50,"Y","N") -> Y
B34: 24 | C34: =[3]Theory!A48 -> 2023-IT-40 | D34: =[3]Theory!B48 -> Ahmad Raza Shareef | E34: =[3]Theory!D48 -> 5 | F34: 8 | G34: 2 | H34: 3 | I34: =[3]Theory!E48 -> 13 | J34: =[3]Theory!H48 -> 10 | K34: =[3]Theory!F48 -> 9 | L34: 4 | M34: 6 | N34: 7 | O34: =[3]Theory!G48 -> 17 | P34: =E34+I34+J34+K34+O34 -> 54 | Q34: =[3]Theory!J48 -> B- | S34: =E34+F34+L34+J34+N34 -> 34 | T34: =G34+H34+K34+M34 -> 20 | V34: =((S34/$S$7)*100) -> 60.714286 | W34: =((T34/$T$7)*100) -> 45.454545 | Y34: =IF(V34>=50,"Y","N") -> Y | Z34: =IF(W34>=50,"Y","N") -> N
B35: 25 | C35: =[3]Theory!A49 -> 2023-IT-41 | D35: =[3]Theory!B49 -> Anas Noor | E35: =[3]Theory!D49 -> 5 | F35: 3 | G35: 1 | H35: 1 | I35: =[3]Theory!E49 -> 5 | J35: =[3]Theory!H49 -> 9 | K35: =[3]Theory!F49 -> 7 | L35: 7 | M35: 1 | N35: 2 | O35: =[3]Theory!G49 -> 10 | P35: =E35+I35+J35+K35+O35 -> 36 | Q35: =[3]Theory!J49 -> D | S35: =E35+F35+L35+J35+N35 -> 26 | T35: =G35+H35+K35+M35 -> 10 | V35: =((S35/$S$7)*100) -> 46.428571 | W35: =((T35/$T$7)*100) -> 22.727273 | Y35: =IF(V35>=50,"Y","N") -> N | Z35: =IF(W35>=50,"Y","N") -> N
B36: 26 | C36: =[3]Theory!A50 -> 2023-IT-42 | D36: =[3]Theory!B50 -> Muhammad Moosa Bhatti | E36: =[3]Theory!D50 -> 3 | F36: 8 | G36: 2 | H36: 1 | I36: =[3]Theory!E50 -> 11 | J36: =[3]Theory!H50 -> 8 | K36: =[3]Theory!F50 -> 7 | L36: 3 | M36: 8 | N36: 9 | O36: =[3]Theory!G50 -> 20 | P36: =E36+I36+J36+K36+O36 -> 49 | Q36: =[3]Theory!J50 -> C+ | S36: =E36+F36+L36+J36+N36 -> 31 | T36: =G36+H36+K36+M36 -> 18 | V36: =((S36/$S$7)*100) -> 55.357143 | W36: =((T36/$T$7)*100) -> 40.909091 | Y36: =IF(V36>=50,"Y","N") -> Y | Z36: =IF(W36>=50,"Y","N") -> N
B37: 27 | C37: =[3]Theory!A51 -> 2023-IT-44 | D37: =[3]Theory!B51 -> Muhammad Nouman Aslam | E37: =[3]Theory!D51 -> 5 | F37: 9 | G37: 5 | H37: 8 | I37: =[3]Theory!E51 -> 22 | J37: =[3]Theory!H51 -> 7 | K37: =[3]Theory!F51 -> 6 | L37: 3 | M37: 6 | N37: 10 | O37: =[3]Theory!G51 -> 19 | P37: =E37+I37+J37+K37+O37 -> 59 | Q37: =[3]Theory!J51 -> B | S37: =E37+F37+L37+J37+N37 -> 34 | T37: =G37+H37+K37+M37 -> 25 | V37: =((S37/$S$7)*100) -> 60.714286 | W37: =((T37/$T$7)*100) -> 56.818182 | Y37: =IF(V37>=50,"Y","N") -> Y | Z37: =IF(W37>=50,"Y","N") -> Y
B38: 28 | C38: =[3]Theory!A52 -> 2023-IT-46 | D38: =[3]Theory!B52 -> Muhammad Haseeb Anjum | E38: =[3]Theory!D52 -> 9 | F38: 8 | G38: 10 | H38: 8 | I38: =[3]Theory!E52 -> 26 | J38: =[3]Theory!H52 -> 8 | K38: =[3]Theory!F52 -> 10 | L38: 10 | M38: 14 | N38: 15 | O38: =[3]Theory!G52 -> 39 | P38: =E38+I38+J38+K38+O38 -> 92 | Q38: =[3]Theory!J52 -> A+ | S38: =E38+F38+L38+J38+N38 -> 50 | T38: =G38+H38+K38+M38 -> 42 | V38: =((S38/$S$7)*100) -> 89.285714 | W38: =((T38/$T$7)*100) -> 95.454545 | Y38: =IF(V38>=50,"Y","N") -> Y | Z38: =IF(W38>=50,"Y","N") -> Y
B39: 29 | C39: =[3]Theory!A53 -> 2023-IT-48 | D39: =[3]Theory!B53 -> Muhammad Arslan Waheed | E39: =[3]Theory!D53 -> 6 | F39: 8 | G39: 2 | H39: 9 | I39: =[3]Theory!E53 -> 19 | J39: =[3]Theory!H53 -> 8 | K39: =[3]Theory!F53 -> 6 | L39: 8 | M39: 10 | N39: 14 | O39: =[3]Theory!G53 -> 32 | P39: =E39+I39+J39+K39+O39 -> 71 | Q39: =[3]Theory!J53 -> A- | S39: =E39+F39+L39+J39+N39 -> 44 | T39: =G39+H39+K39+M39 -> 27 | V39: =((S39/$S$7)*100) -> 78.571429 | W39: =((T39/$T$7)*100) -> 61.363636 | Y39: =IF(V39>=50,"Y","N") -> Y | Z39: =IF(W39>=50,"Y","N") -> Y
B40: 30 | C40: =[3]Theory!A54 -> 2023-IT-50 | D40: =[3]Theory!B54 -> Hafiz Muhammad Hasnain Saif | E40: =[3]Theory!D54 -> 10 | F40: 8 | G40: 10 | H40: 8 | I40: =[3]Theory!E54 -> 26 | J40: =[3]Theory!H54 -> 8 | K40: =[3]Theory!F54 -> 9 | L40: 2 | M40: 10 | N40: 15 | O40: =[3]Theory!G54 -> 27 | P40: =E40+I40+J40+K40+O40 -> 80 | Q40: =[3]Theory!J54 -> A- | S40: =E40+F40+L40+J40+N40 -> 43 | T40: =G40+H40+K40+M40 -> 37 | V40: =((S40/$S$7)*100) -> 76.785714 | W40: =((T40/$T$7)*100) -> 84.090909 | Y40: =IF(V40>=50,"Y","N") -> Y | Z40: =IF(W40>=50,"Y","N") -> Y
B41: 31 | C41: =[3]Theory!A55 -> 2023-IT-54 | D41: =[3]Theory!B55 -> Muhammad Zeeshan | E41: =[3]Theory!D55 -> 6 | F41: 8 | G41: 4 | H41: 2 | I41: =[3]Theory!E55 -> 14 | J41: =[3]Theory!H55 -> 8 | K41: =[3]Theory!F55 -> 6 | L41: 0 | M41: 6 | N41: 1 | O41: =[3]Theory!G55 -> 7 | P41: =E41+I41+J41+K41+O41 -> 41 | Q41: =[3]Theory!J55 -> C- | S41: =E41+F41+L41+J41+N41 -> 23 | T41: =G41+H41+K41+M41 -> 18 | V41: =((S41/$S$7)*100) -> 41.071429 | W41: =((T41/$T$7)*100) -> 40.909091 | Y41: =IF(V41>=50,"Y","N") -> N | Z41: =IF(W41>=50,"Y","N") -> N
... B54: 44 | C54: =[3]Theory!A68 -> 2023-IT-80 | D54: =[3]Theory!B68 -> Ali Raza | E54: =[3]Theory!D68 -> 1 | F54: 10 | G54: 6 | H54: 4 | I54: =[3]Theory!E68 -> 20 | J54: =[3]Theory!H68 -> 7 | K54: =[3]Theory!F68 -> 7 | L54: 1 | M54: 9 | N54: 4 | O54: =[3]Theory!G68 -> 14 | P54: =E54+I54+J54+K54+O54 -> 49 | Q54: =[3]Theory!J68 -> C+ | S54: =E54+F54+L54+J54+N54 -> 23 | T54: =G54+H54+K54+M54 -> 26 | V54: =((S54/$S$7)*100) -> 41.071429 | W54: =((T54/$T$7)*100) -> 59.090909 | Y54: =IF(V54>=50,"Y","N") -> N | Z54: =IF(W54>=50,"Y","N") -> Y
B57: Teacher Incharge Signature
B58: =D64 -> Muhammad Aamir | F58: (Engr. M. Kashan Basit)
B62: =B1 -> MNS - UNIVERSITY OF ENGINEERING AND TECHNOLOGY MULTAN
...

Sheet Application of Information & Co
B2: MNS - UNIVERSITY OF ENGINEERING AND TECHNOLOGY MULTAN | N2: Fall 2023 | T2: Evening (A)
B3: Activity Sheet | N3: CLO & PLO Assesment
B4: Subject: | I4: Title (Code): Application of Information & Communication Technologies (IT-112 | N4: Name: Ms. Kanza Hanif
B5: Component Name | E5: =#REF! -> #REF! | I5: =#REF! -> #REF! | J5: =#REF! -> #REF! | K5: =#REF! -> #REF! | L5: Total | M5: Grade | N5: CLOs vs. PLOs
D6: Total Marks | E6: 30 | H6: Total | I6: 20 | J6: 10 | K6: 40 | L6: =E6+I6+J6+K6 -> 100 | N6: CLOs | O6: 1 | P6: 2 | Q6: 3
D7: Question Components | E7: R1 | F7: R2 | G7: R3 | I7: Q1 | J7: Q1 | K7: Q1 | L7: =E8+F8+G8+I8+J8+K8 -> 100 | N7: PLOs | O7: 2 | P7: 3 | Q7: 7
D8: Component Marks | E8: 10 | F8: 10 | G8: 10 | H8: 30 | I8: 20 | J8: 10 | K8: 40 | O8: =E8+J8 -> 20 | P8: =K8 -> 40 | Q8: =F8+G8+I8 -> 40
D9: KPI | E9: =E8*0.5 -> 5 | F9: =F8*0.5 -> 5 | G9: =G8*0.5 -> 5 | H9: =H8*0.5 -> 15 | I9: =I8*0.5 -> 10 | J9: =J8*0.5 -> 5 | K9: =K8*0.5 -> 20 | L9: =L7*0.5 -> 50 | O9: Assessment of CLOs | R9: CLOs Acheivement | U9: PLOs Acheivement
D10: CLO Mapping | E10: 1 | F10: 3 | G10: 3 | I10: 3 | J10: 1 | K10: 2 | O10: =O6 -> 1 | P10: =P6 -> 2 | Q10: 3 | R10: 1 | S10: 2 | T10: 3 | U10: =O7 -> 2 | V10: =P7 -> 3 | W10: =Q7 -> 7
B11: Sr. No. | C11: Registration No. | D11: Registration No. | U11: Y | V11: N
B12: 1 | C12: 2023-IT-01 | D12: Rahma Noor | E12: 6 | F12: 5 | G12: 6 | H12: =SUM(E12:G12) -> 17 | I12: 11 | J12: 6 | K12: 21 | L12: =H12+I12+J12+K12 -> 55 | M12: B | O12: =E12+J12 -> 12 | P12: =K12 -> 21 | Q12: =F12+G12+I12 -> 22 | R12: =((O12/$O$8)*100) -> 60 | S12: =((P12/$P$8)*100) -> 52.5 | T12: =((Q12/$Q$8)*100) -> 55 | U12: =IF(R12>=50,"Y","N") -> Y | V12: =IF(S12>50,"Y","N") -> Y | W12: =IF(T12>50,"Y","N") -> Y
B13: 2 | C13: 2023-IT-02 | D13: Alishba Manzoor | E13: 5 | F13: 6 | G13: 5 | H13: =SUM(E13:G13) -> 16 | I13: 11 | J13: 5 | K13: 15 | L13: =H13+I13+J13+K13 -> 47 | M13: C+ | O13: =E13+J13 -> 10 | P13: =K13 -> 15 | Q13: =F13+G13+I13 -> 22 | R13: =((O13/$O$8)*100) -> 50 | S13: =((P13/$P$8)*100) -> 37.5 | T13: =((Q13/$Q$8)*100) -> 55 | U13: =IF(R13>=50,"Y","N") -> Y | V13: =IF(S13>50,"Y","N") -> N | W13: =IF(T13>50,"Y","N") -> Y
B14: 3 | C14: 2023-IT-03 | D14: Maheen Fatima | E14: 5 | F14: 5 | G14: 8 | H14: =SUM(E14:G14) -> 18 | I14: 11 | J14: 6 | K14: 22 | L14: =H14+I14+J14+K14 -> 57 | M14: B | O14: =E14+J14 -> 11 | P14: =K14 -> 22 | Q14: =F14+G14+I14 -> 24 | R14: =((O14/$O$8)*100) -> 55 | S14: =((P14/$P$8)*100) -> 55 | T14: =((Q14/$Q$8)*100) -> 60 | U14: =IF(R14>=50,"Y","N") -> Y | V14: =IF(S14>50,"Y","N") -> Y | W14: =IF(T14>50,"Y","N") -> Y
B15: 4 | C15: 2023-IT-04 | D15: Aneela | E15: 8 | F15: 7 | G15: 7 | H15: =SUM(E15:G15) -> 22 | I15: 12 | J15: 6 | K15: 21 | L15: =H15+I15+J15+K15 -> 61 | M15: B+ | O15: =E15+J15 -> 14 | P15: =K15 -> 21 | Q15: =F15+G15+I15 -> 26 | R15: =((O15/$O$8)*100) -> 70 | S15: =((P15/$P$8)*100) -> 52.5 | T15: =((Q15/$Q$8)*100) -> 65 | U15: =IF(R15>=50,"Y","N") -> Y | V15: =IF(S15>50,"Y","N") -> Y | W15: =IF(T15>50,"Y","N") -> Y
B16: 5 | C16: 2023-IT-05 | D16: Alishba Saleem | E16: 6 | F16: 5 | G16: 5 | H16: =SUM(E16:G16) -> 16 | I16: 11 | J16: 5 | K16: 22 | L16: =H16+I16+J16+K16 -> 54 | M16: B- | O16: =E16+J16 -> 11 | P16: =K16 -> 22 | Q16: =F16+G16+I16 -> 21 | R16: =((O16/$O$8)*100) -> 55 | S16: =((P16/$P$8)*100) -> 55 | T16: =((Q16/$Q$8)*100) -> 52.5 | U16: =IF(R16>=50,"Y","N") -> Y | V16: =IF(S16>50,"Y","N") -> Y | W16: =IF(T16>50,"Y","N") -> Y
B17: 6 | C17: 2023-IT-06 | D17: Mehak Asghar | E17: 8 | F17: 9 | G17: 8 | H17: =SUM(E17:G17) -> 25 | I17: 15 | J17: 7 | K17: 21 | L17: =H17+I17+J17+K17 -> 68 | M17: A- | O17: =E17+J17 -> 15 | P17: =K17 -> 21 | Q17: =F17+G17+I17 -> 32 | R17: =((O17/$O$8)*100) -> 75 | S17: =((P17/$P$8)*100) -> 52.5 | T17: =((Q17/$Q$8)*100) -> 80 | U17: =IF(R17>=50,"Y","N") -> Y | V17: =IF(S17>50,"Y","N") -> Y | W17: =IF(T17>50,"Y","N") -> Y
B18: 7 | C18: 2023-IT-07 | D18: Humaira Afzal | E18: 5 | F18: 7 | G18: 9 | H18: =SUM(E18:G18) -> 21 | I18: 15 | J18: 8 | K18: 23 | L18: =H18+I18+J18+K18 -> 67 | M18: A- | O18: =E18+J18 -> 13 | P18: =K18 -> 23 | Q18: =F18+G18+I18 -> 31 | R18: =((O18/$O$8)*100) -> 65 | S18: =((P18/$P$8)*100) -> 57.5 | T18: =((Q18/$Q$8)*100) -> 77.5 | U18: =IF(R18>=50,"Y","N") -> Y | V18: =IF(S18>50,"Y","N") -> Y | W18: =IF(T18>50,"Y","N") -> Y
B19: 8 | C19: 2023-IT-08 | D19: Saleena Khan | E19: 0 | F19: 0 | G19: 0 | H19: =SUM(E19:G19) -> 0 | I19: 0 | J19: 0 | K19: 0 | L19: =H19+I19+J19+K19 -> 0 | M19: F | O19: =E19+J19 -> 0 | P19: =K19 -> 0 | Q19: =F19+G19+I19 -> 0 | R19: =((O19/$O$8)*100) -> 0 | S19: =((P19/$P$8)*100) -> 0 | T19: =((Q19/$Q$8)*100) -> 0 | U19: =IF(R19>=50,"Y","N") -> N | V19: =IF(S19>50,"Y","N") -> N | W19: =IF(T19>50,"Y","N") -> N
B20: 9 | C20: 2023-IT-10 | D20: Asad Ullah | E20: 8 | F20: 7 | G20: 6 | H20: =SUM(E20:G20) -> 21 | I20: 13 | J20: 7 | K20: 20 | L20: =H20+I20+J20+K20 -> 61 | M20: B+ | O20: =E20+J20 -> 15 | P20: =K20 -> 20 | Q20: =F20+G20+I20 -> 26 | R20: =((O20/$O$8)*100) -> 75 | S20: =((P20/$P$8)*100) -> 50 | T20: =((Q20/$Q$8)*100) -> 65 | U20: =IF(R20>=50,"Y","N") -> Y | V20: =IF(S20>50,"Y","N") -> N | W20: =IF(T20>50,"Y","N") -> Y
B21: 10 | C21: 2023-IT-11 | D21: Rana Talha dawood | E21: 7 | F21: 6 | G21: 5 | H21: =SUM(E21:G21) -> 18 | I21: 13 | J21: 7 | K21: 20 | L21: =H21+I21+J21+K21 -> 58 | M21: B | O21: =E21+J21 -> 14 | P21: =K21 -> 20 | Q21: =F21+G21+I21 -> 24 | R21: =((O21/$O$8)*100) -> 70 | S21: =((P21/$P$8)*100) -> 50 | T21: =((Q21/$Q$8)*100) -> 60 | U21: =IF(R21>=50,"Y","N") -> Y | V21: =IF(S21>50,"Y","N") -> N | W21: =IF(T21>50,"Y","N") -> Y
B22: 11 | C22: 2023-IT-12 | D22: Ali Ahmad | E22: 5 | F22: 5 | G22: 8 | H22: =SUM(E22:G22) -> 18 | I22: 11 | J22: 5 | K22: 21 | L22: =H22+I22+J22+K22 -> 55 | M22: B | O22: =E22+J22 -> 10 | P22: =K22 -> 21 | Q22: =F22+G22+I22 -> 24 | R22: =((O22/$O$8)*100) -> 50 | S22: =((P22/$P$8)*100) -> 52.5 | T22: =((Q22/$Q$8)*100) -> 60 | U22: =IF(R22>=50,"Y","N") -> Y | V22: =IF(S22>50,"Y","N") -> Y | W22: =IF(T22>50,"Y","N") -> Y
B23: 12 | C23: 2023-IT-13 | D23: Muhammad Daud | E23: 5 | F23: 5 | G23: 5 | H23: =SUM(E23:G23) -> 15 | I23: 10 | J23: 5 | K23: 20 | L23: =H23+I23+J23+K23 -> 50 | M23: B- | O23: =E23+J23 -> 10 | P23: =K23 -> 20 | Q23: =F23+G23+I23 -> 20 | R23: =((O23/$O$8)*100) -> 50 | S23: =((P23/$P$8)*100) -> 50 | T23: =((Q23/$Q$8)*100) -> 50 | U23: =IF(R23>=50,"Y","N") -> Y | V23: =IF(S23>50,"Y","N") -> N | W23: =IF(T23>50,"Y","N") -> N
... B55: 28 | C55: 2023-IT-80 | D55: Ali Raza | E55: 6 | F55: 6 | G55: 5 | H55: =SUM(E55:G55) -> 17 | I55: 6 | J55: 5 | K55: 28 | L55: =H55+I55+J55+K55 -> 56 | M55: B | O55: =E55+J55 -> 11 | P55: =K55 -> 28 | Q55: =F55+G55+I55 -> 17 | R55: =((O55/$O$8)*100) -> 55 | S55: =((P55/$P$8)*100) -> 70 | T55: =((Q55/$Q$8)*100) -> 42.5 | U55: =IF(R55>=50,"Y","N") -> Y | V55: =IF(S55>50,"Y","N") -> Y | W55: =IF(T55>50,"Y","N") -> N
C60: Teacher Incharge Signature | E60: Incharge Department Signature
C61: Ms. Kanza Hanif | E61: (Engr. M. Kashan Basit)
B63: CLO-1 | C63: Follow instructions to identify the knowledge of constructing basic circuits and demonstration of relevant theorems using different electronic components(PLO-2, C-2)
B65: CLO-2 | C65: Practice the experiment as per requirement using modern tools. (PLO-5, P-4)
B67: CLO-3 | C67: Ability to communicate effectively; orally as well as in writing. (PLO-7, A-2)
B70: =B2 -> MNS - UNIVERSITY OF ENGINEERING AND TECHNOLOGY MULTAN
B71: Department of Computer Science
B72: =I4 -> Title (Code): Application of Information & Communication Technologies (IT-112 | D72: =N2 -> Fall 2023
B73: Session 2023 | D73: =T2 -> Evening (A)
B74: Activity Sheet Statistics
D77: No. of Students
B78: Sr. No. | C78: PLO | D78: Achieved the PLO | E78: Not Achieved the PLO | F78: CF
B79: 1 | C79: =O7 -> 2 | D79: =COUNTIF($U$12:$U$55,U12) -> 38 | E79: =COUNTIF($U$12:$U$53,V11) -> 6 | F79: =E79/39*100 -> 15.384615
B80: 2 | C80: =P7 -> 3 | D80: =COUNTIF($U$12:$U$55,U49) -> 6 | E80: =COUNTIF($V$12:$V$53,V11) -> 17 | F80: =E80/39*100 -> 43.589744
B81: 3 | C81: =Q7 -> 7 | D81: =COUNTIF($U$12:$U$55,U50) -> 38 | E81: =COUNTIF($W$12:$W$53,V11) -> 9 | F81: =E81/39*100 -> 23.076923
C110: Cohert Failure =

Sheet Teaching of Holy Quran with Tra
B1: =[4]Theory!A1 -> MNS - UNIVERSITY OF ENGINEERING AND TECHNOLOGY MULTAN | L1: =[4]Theory!B4 -> Fall-2023-2027 (Evening-A) | P1: =[4]Theory!H3 -> 1st Semester | S1: =[4]Theory!H4 -> Fall 2023 | X1: =[4]Theory!H5 -> Abdul Nasir Zamir
B2: Activity Sheet | I2: =[4]Theory!B3 -> BS Information Technology | R2: CLO & PLO Assessment
B3: Subject: | E3: =[4]Theory!B5 -> Title (Code): Teaching of the Holy Quran-I (QS-110)
B4: Component Name | E4: Quiz 1 | F4: Mid Term | J4: C.P | K4: Quiz 2 | L4: Final Term | P4: Total | Q4: Grade | R4: CLOs vs. PLOs
B5: Total Marks | E5: 10 | F5: 30 | J5: 10 | K5: 10 | L5: 16 | M5: 14 | N5: 10 | O5: 40 | P5: =SUM(E5:N5) -> 100 | R5: CLOs | S5: 1 | T5: 2 | U5: 3
B6: Question Components | E6: Q 1 | F6: Q1 | G6: Q2 | H6: Q3 | I6: Total | J6: Q1 | K6: Q1 | L6: Q1 | M6: Q2 | N6: Q3 | O6: Total | R6: PLOs | S6: 1
B7: Component Marks | E7: 10 | F7: 10 | G7: 10 | H7: 10 | I7: =F7+G7+H7 -> 30 | J7: 10 | K7: 10 | L7: 14 | M7: 10 | N7: 16 | O7: 40 | P7: =SUM(E7:H7,J7:N7) -> 100 | S7: 100
D8: KPI | E8: =E7*0.5 -> 5 | F8: =F7*0.5 -> 5 | G8: =G7*0.5 -> 5 | H8: =H7*0.5 -> 5 | I8: =I7*0.5 -> 15 | J8: =J7*0.5 -> 5 | K8: =K7*0.5 -> 5 | L8: =L7*0.5 -> 7 | ... O8: =O7*0.5 -> 20 | P8: =SUM(E8:H8)+SUM(J8:J8)+SUM(K8:N8) -> 50 | S8: Assessment of CLOs | V8: PLOs Acheivement | Y8: PLOs Acheivement
D9: CLO Mapping | E9: 1 | F9: 1 | G9: 2 | H9: 2 | J9: 3 | K9: 2 | L9: 1 | M9: 2 | N9: 3 | S9: =S5 -> 1 | T9: =T5 -> 2 | U9: 3 | V9: 1 | W9: 1 | X9: 1 | Y9: =S6 -> 1
B10: Sr. No. | C10: Registration No. | D10: Student Name | Y10: Y
B11: 1 | C11: =[4]Theory!A25 -> 2023-IT-01 | D11: =[4]Theory!B25 -> Rahma Noor | E11: =[4]Theory!D25 -> 2 | F11: 8 | G11: 8 | H11: 8 | I11: =[4]Theory!E25 -> 24 | J11: =[4]Theory!H25 -> 9 | K11: =[4]Theory!F25 -> 8 | L11: 10 | M11: 10 | N11: 11 | O11: =[4]Theory!G25 -> 31 | P11: =E11+I11+J11+K11+O11 -> 74 | Q11: =[4]Theory!J25 -> B+ | S11: =E11+F11+L11 -> 20 | T11: =G11+H11+K11+M11 -> 34 | U11: =J11+N11 -> 20 | V11: =((SUM(S11:U11)/$S$7)*100) -> 74 | Y11: =IF(V11>=50,"Y","N") -> Y
B12: 2 | C12: =[4]Theory!A26 -> 2023-IT-02 | D12: =[4]Theory!B26 -> Alishba Manzoor | E12: =[4]Theory!D26 -> 2 | F12: 8 | G12: 9 | H12: 9 | I12: =[4]Theory!E26 -> 25 | J12: =[4]Theory!H26 -> 8 | K12: =[4]Theory!F26 -> 9 | L12: 10 | M12: 5 | N12: 10 | O12: =[4]Theory!G26 -> 25 | P12: =E12+I12+J12+K12+O12 -> 69 | Q12: =[4]Theory!J26 -> B | S12: =E12+F12+L12 -> 20 | T12: =G12+H12+K12+M12 -> 32 | U12: =J12+N12 -> 18 | V12: =((SUM(S12:U12)/$S$7)*100) -> 70 | Y12: =IF(V12>=50,"Y","N") -> Y
B13: 3 | C13: =[4]Theory!A27 -> 2023-IT-03 | D13: =[4]Theory!B27 -> Maheen Fatima | E13: =[4]Theory!D27 -> 2 | F13: 7 | G13: 8 | H13: 8 | I13: =[4]Theory!E27 -> 23 | J13: =[4]Theory!H27 -> 7 | K13: =[4]Theory!F27 -> 10 | L13: 10 | M13: 10 | N13: 6 | O13: =[4]Theory!G27 -> 26 | P13: =E13+I13+J13+K13+O13 -> 68 | Q13: =[4]Theory!J27 -> B | S13: =E13+F13+L13 -> 19 | T13: =G13+H13+K13+M13 -> 36 | U13: =J13+N13 -> 13 | V13: =((SUM(S13:U13)/$S$7)*100) -> 68 | Y13: =IF(V13>=50,"Y","N") -> Y
B14: 4 | C14: =[4]Theory!A28 -> 2023-IT-04 | D14: =[4]Theory!B28 -> Aneela | E14: =[4]Theory!D28 -> 6 | F14: 7 | G14: 7 | H14: 9 | I14: =[4]Theory!E28 -> 23 | J14: =[4]Theory!H28 -> 8 | K14: =[4]Theory!F28 -> 10 | L14: 8 | M14: 7 | N14: 10 | O14: =[4]Theory!G28 -> 25 | P14: =E14+I14+J14+K14+O14 -> 72 | Q14: =[4]Theory!J28 -> B+ | S14: =E14+F14+L14 -> 21 | T14: =G14+H14+K14+M14 -> 33 | U14: =J14+N14 -> 18 | V14: =((SUM(S14:U14)/$S$7)*100) -> 72 | Y14: =IF(V14>=50,"Y","N") -> Y
B15: 5 | C15: =[4]Theory!A29 -> 2023-IT-05 | D15: =[4]Theory!B29 -> Alishba Saleem | E15: =[4]Theory!D29 -> 4 | F15: 9 | G15: 4 | H15: 10 | I15: =[4]Theory!E29 -> 25 | J15: =[4]Theory!H29 -> 8 | K15: =[4]Theory!F29 -> 7 | L15: 8 | M15: 8 | N15: 6 | O15: =[4]Theory!G29 -> 22 | P15: =E15+I15+J15+K15+O15 -> 66 | Q15: =[4]Theory!J29 -> B | S15: =E15+F15+L15 -> 21 | T15: =G15+H15+K15+M15 -> 29 | U15: =J15+N15 -> 14 | V15: =((SUM(S15:U15)/$S$7)*100) -> 64 | Y15: =IF(V15>=50,"Y","N") -> Y
B16: 6 | C16: =[4]Theory!A30 -> 2023-IT-06 | D16: =[4]Theory!B30 -> Mehak Asghar | E16: =[4]Theory!D30 -> 7 | F16: 8 | G16: 7 | H16: 9 | I16: =[4]Theory!E30 -> 24 | J16: =[4]Theory!H30 -> 7 | K16: =[4]Theory!F30 -> 10 | L16: 8 | M16: 10 | N16: 7 | O16: =[4]Theory!G30 -> 25 | P16: =E16+I16+J16+K16+O16 -> 73 | Q16: =[4]Theory!J30 -> B+ | S16: =E16+F16+L16 -> 23 | T16: =G16+H16+K16+M16 -> 36 | U16: =J16+N16 -> 14 | V16: =((SUM(S16:U16)/$S$7)*100) -> 73 | Y16: =IF(V16>=50,"Y","N") -> Y
B17: 7 | C17: =[4]Theory!A31 -> 2023-IT-07 | D17: =[4]Theory!B31 -> Humaira Afzal | E17: =[4]Theory!D31 -> 8 | F17: 7 | G17: 8 | H17: 9 | I17: =[4]Theory!E31 -> 24 | J17: =[4]Theory!H31 -> 8 | K17: =[4]Theory!F31 -> 9 | L17: 12 | M17: 10 | N17: 11 | O17: =[4]Theory!G31 -> 33 | P17: =E17+I17+J17+K17+O17 -> 82 | Q17: =[4]Theory!J31 -> A- | S17: =E17+F17+L17 -> 27 | T17: =G17+H17+K17+M17 -> 36 | U17: =J17+N17 -> 19 | V17: =((SUM(S17:U17)/$S$7)*100) -> 82 | Y17: =IF(V17>=50,"Y","N") -> Y
B18: 8 | C18: =[4]Theory!A32 -> 2023-IT-08 | D18: =[4]Theory!B32 -> Saleena Khan | E18: =[4]Theory!D32 -> 0 | F18: 0 | G18: 0 | H18: 0 | I18: =[4]Theory!E32 -> 0 | J18: =[4]Theory!H32 -> 0 | K18: =[4]Theory!F32 -> 0 | L18: 0 | M18: 0 | N18: 0 | O18: =[4]Theory!G32 -> 0 | P18: =E18+I18+J18+K18+O18 -> 0 | Q18: =[4]Theory!J32 -> F | S18: =E18+F18+L18 -> 0 | T18: =G18+H18+K18+M18 -> 0 | U18: =J18+N18 -> 0 | V18: =((SUM(S18:U18)/$S$7)*100) -> 0 | Y18: =IF(V18>=50,"Y","N") -> N
B19: 9 | C19: =[4]Theory!A33 -> 2023-IT-10 | D19: =[4]Theory!B33 -> Asad Ullah | E19: =[4]Theory!D33 -> 5 | F19: 9 | G19: 6 | H19: 10 | I19: =[4]Theory!E33 -> 25 | J19: =[4]Theory!H33 -> 9 | K19: =[4]Theory!F33 -> 10 | L19: 11 | M19: 9 | N19: 7 | O19: =[4]Theory!G33 -> 27 | P19: =E19+I19+J19+K19+O19 -> 76 | Q19: =[4]Theory!J33 -> B+ | S19: =E19+F19+L19 -> 25 | T19: =G19+H19+K19+M19 -> 35 | U19: =J19+N19 -> 16 | V19: =((SUM(S19:U19)/$S$7)*100) -> 76 | Y19: =IF(V19>=50,"Y","N") -> Y
B20: 10 | C20: =[4]Theory!A34 -> 2023-IT-11 | D20: =[4]Theory!B34 -> Rana Talha dawood | E20: =[4]Theory!D34 -> 5 | F20: 8 | G20: 7 | H20: 8 | I20: =[4]Theory!E34 -> 23 | J20: =[4]Theory!H34 -> 8 | K20: =[4]Theory!F34 -> 10 | L20: 9 | M20: 10 | N20: 10 | O20: =[4]Theory!G34 -> 29 | P20: =E20+I20+J20+K20+O20 -> 75 | Q20: =[4]Theory!J34 -> B+ | S20: =E20+F20+L20 -> 22 | T20: =G20+H20+K20+M20 -> 35 | U20: =J20+N20 -> 18 | V20: =((SUM(S20:U20)/$S$7)*100) -> 75 | Y20: =IF(V20>=50,"Y","N") -> Y
B21: 11 | C21: =[4]Theory!A35 -> 2023-IT-12 | D21: =[4]Theory!B35 -> Ali Ahmad | E21: =[4]Theory!D35 -> 7 | F21: 8 | G21: 8 | H21: 8 | I21: =[4]Theory!E35 -> 24 | J21: =[4]Theory!H35 -> 7 | K21: =[4]Theory!F35 -> 9 | L21: 14 | M21: 10 | N21: 9 | O21: =[4]Theory!G35 -> 33 | P21: =E21+I21+J21+K21+O21 -> 80 | Q21: =[4]Theory!J35 -> A- | S21: =E21+F21+L21 -> 29 | T21: =G21+H21+K21+M21 -> 35 | U21: =J21+N21 -> 16 | V21: =((SUM(S21:U21)/$S$7)*100) -> 80 | Y21: =IF(V21>=50,"Y","N") -> Y
B22: 12 | C22: =[4]Theory!A36 -> 2023-IT-13 | D22: =[4]Theory!B36 -> Muhammad Daud | E22: =[4]Theory!D36 -> 5 | F22: 9 | G22: 7 | H22: 7 | I22: =[4]Theory!E36 -> 23 | J22: =[4]Theory!H36 -> 8 | K22: =[4]Theory!F36 -> 9 | L22: 10 | M22: 10 | N22: 12 | O22: =[4]Theory!G36 -> 32 | P22: =E22+I22+J22+K22+O22 -> 77 | Q22: =[4]Theory!J36 -> B+ | S22: =E22+F22+L22 -> 24 | T22: =G22+H22+K22+M22 -> 33 | U22: =J22+N22 -> 20 | V22: =((SUM(S22:U22)/$S$7)*100) -> 77 | Y22: =IF(V22>=50,"Y","N") -> Y
... B54: 44 | C54: =[4]Theory!A68 -> 2023-IT-80 | D54: =[4]Theory!B68 -> Ali Raza | E54: =[4]Theory!D68 -> 6 | F54: 9 | G54: 9 | H54: 7 | I54: =[4]Theory!E68 -> 25 | J54: =[4]Theory!H68 -> 8 | K54: =[4]Theory!F68 -> 10 | L54: 10 | M54: 8 | N54: 7 | O54: =[4]Theory!G68 -> 25 | P54: =E54+I54+J54+K54+O54 -> 74 | Q54: =[4]Theory!J68 -> B+ | S54: =E54+F54+L54 -> 25 | T54: =G54+H54+K54+M54 -> 34 | U54: =J54+N54 -> 15 | V54: =((SUM(S54:U54)/$S$7)*100) -> 74 | Y54: =IF(V54>=50,"Y","N") -> Y
B57: Teacher Incharge Signature | F57: Incharge Department Signature
B58: =D64 -> Abdul Nasir Zamir | F58: (Engr. M. Kashan Basit)
B62: =B1 -> MNS - UNIVERSITY OF ENGINEERING AND TECHNOLOGY MULTAN
B63: =E3 -> Title (Code): Teaching of the Holy Quran-I (QS-110) | D63: =S1 -> Fall 2023
D64: =X1 -> Abdul Nasir Zamir
B65: Activity Sheet Statistics
D68: No. of Students
B69: Sr. No. | C69: PLO | D69: Achieved the PLO | F69: Not Achieved the PLO
B70: 1 | C70: =S6 -> 1 | D70: =COUNTIF($Y$11:$Y$55,Y10) -> 38 | F70: =COUNTIF($Y$11:$Y$55,Z10) -> 0
B71: 2 | C71: =T6 -> 0 | D71: =COUNTIF($Z$11:$Z$55,Z11) -> 0 | F71: =COUNTIF($Z$11:$Z$55,Z10) -> 0
B72: 3 | C72: =U6 -> 0 | D72: =COUNTIF($AA$11:$AA$55,Y10) -> 0 | F72: =COUNTIF($AA$11:$AA$55,Z10) -> 0
C101: Cohert Failure =

Sheet Functional English
B1: =[5]Theory!A1 -> MNS - UNIVERSITY OF ENGINEERING AND TECHNOLOGY MULTAN | L1: =[5]Theory!B4 -> Fall-2023-2027 (Evening-A) | P1: =[5]Theory!H3 -> 1st Semester | S1: =[5]Theory!H4 -> Fall 2023 | X1: =[5]Theory!H5 -> Hina Zulfiqar
B2: Activity Sheet | I2: =[5]Theory!B3 -> BS Information Technology | R2: CLO & PLO Assessment
B3: Subject: | E3: =[5]Theory!B5 -> Title (Code): Functional English (ENG-115)
B4: Component Name | E4: Quiz 1 | F4: Mid Term | J4: C.P | K4: Quiz 2 | L4: Final Term | P4: Total | Q4: Grade | R4: CLOs vs. PLOs
B5: Total Marks | E5: 10 | F5: 30 | J5: 10 | K5: 10 | L5: 16 | M5: 14 | N5: 10 | O5: 40 | P5: =SUM(E5:N5) -> 100 | R5: CLOs | S5: 1 | T5: 2
B6: Question Components | E6: Q 1 | F6: Q1 | G6: Q2 | H6: Q3 | I6: Total | J6: Q1 | K6: Q1 | L6: Q1 | M6: Q2 | N6: Q3 | O6: Total | R6: PLOs | S6: 1 | T6: 7
B7: Component Marks | E7: 10 | F7: 10 | G7: 10 | H7: 10 | I7: =F7+G7+H7 -> 30 | J7: 10 | K7: 10 | L7: 14 | M7: 16 | N7: 10 | O7: 40 | P7: =SUM(E7:H7,J7:N7) -> 100 | S7: =F7+E7+L7 -> 34 | T7: 66
D8: KPI | E8: =E7*0.5 -> 5 | F8: =F7*0.5 -> 5 | G8: =G7*0.5 -> 5 | H8: =H7*0.5 -> 5 | I8: =I7*0.5 -> 15 | J8: =J7*0.5 -> 5 | K8: =K7*0.5 -> 5 | L8: =L7*0.5 -> 7 | ... O8: =O7*0.5 -> 20 | P8: =SUM(E8:H8)+SUM(J8:J8)+SUM(K8:N8) -> 50 | S8: Assessment of CLOs | V8: PLOs Acheivement | Y8: PLOs Acheivement
D9: CLO Mapping | E9: 1 | F9: 1 | G9: 2 | H9: 2 | J9: 2 | K9: 2 | L9: 1 | M9: 2 | N9: 2 | S9: =S5 -> 1 | T9: =T5 -> 2 | V9: 1 | W9: 7 | Y9: =S6 -> 1 | Z9: =T6 -> 7
B10: Sr. No. | C10: Registration No. | D10: Student Name | Y10: Y | Z10: N
B11: 1 | C11: =[5]Theory!A25 -> 2023-IT-01 | D11: =[5]Theory!B25 -> Rahma Noor | E11: =[5]Theory!D25 -> 6 | F11: 5 | G11: 5 | H11: 0 | I11: =[5]Theory!E25 -> 10 | J11: =[5]Theory!H25 -> 8 | K11: =[5]Theory!F25 -> 9 | L11: 10 | M11: 12 | N11: 4 | O11: =[5]Theory!G25 -> 26 | P11: =E11+I11+J11+K11+O11 -> 59 | Q11: =[5]Theory!J25 -> C+ | S11: =E11+F11+L11 -> 21 | T11: =G11+H11+K11+M11+J11+N11 -> 38 | V11: =((S11/$S$7)*100) -> 61.764706 | W11: =((T11/$T$7)*100) -> 57.575758 | Y11: =IF(V11>=50,"Y","N") -> Y | Z11: =IF(W11>=50,"Y","N") -> Y
B12: 2 | C12: =[5]Theory!A26 -> 2023-IT-02 | D12: =[5]Theory!B26 -> Alishba Manzoor | E12: =[5]Theory!D26 -> 4 | F12: 4 | G12: 5 | H12: 0 | I12: =[5]Theory!E26 -> 9 | J12: =[5]Theory!H26 -> 8 | K12: =[5]Theory!F26 -> 5 | L12: 4 | M12: 7 | N12: 3 | O12: =[5]Theory!G26 -> 14 | P12: =E12+I12+J12+K12+O12 -> 40 | Q12: =[5]Theory!J26 -> C- | S12: =E12+F12+L12 -> 12 | T12: =G12+H12+K12+M12+J12+N12 -> 28 | V12: =((S12/$S$7)*100) -> 35.294118 | W12: =((T12/$T$7)*100) -> 42.424242 | Y12: =IF(V12>=50,"Y","N") -> N | Z12: =IF(W12>=50,"Y","N") -> N
B13: 3 | C13: =[5]Theory!A27 -> 2023-IT-03 | D13: =[5]Theory!B27 -> Maheen Fatima | E13: =[5]Theory!D27 -> 6 | F13: 6 | G13: 4 | H13: 2 | I13: =[5]Theory!E27 -> 12 | J13: =[5]Theory!H27 -> 8 | K13: =[5]Theory!F27 -> 7 | L13: 10 | M13: 10 | N13: 8 | O13: =[5]Theory!G27 -> 28 | P13: =E13+I13+J13+K13+O13 -> 61 | Q13: =[5]Theory!J27 -> B- | S13: =E13+F13+L13 -> 22 | T13: =G13+H13+K13+M13+J13+N13 -> 39 | V13: =((S13/$S$7)*100) -> 64.705882 | W13: =((T13/$T$7)*100) -> 59.090909 | Y13: =IF(V13>=50,"Y","N") -> Y | Z13: =IF(W13>=50,"Y","N") -> Y
B14: 4 | C14: =[5]Theory!A28 -> 2023-IT-04 | D14: =[5]Theory!B28 -> Aneela | E14: =[5]Theory!D28 -> 7 | F14: 8 | G14: 8 | H14: 5 | I14: =[5]Theory!E28 -> 21 | J14: =[5]Theory!H28 -> 8 | K14: =[5]Theory!F28 -> 8 | L14: 12 | M14: 12 | N14: 6 | O14: =[5]Theory!G28 -> 30 | P14: =E14+I14+J14+K14+O14 -> 74 | Q14: =[5]Theory!J28 -> B+ | S14: =E14+F14+L14 -> 27 | T14: =G14+H14+K14+M14+J14+N14 -> 47 | V14: =((S14/$S$7)*100) -> 79.411765 | W14: =((T14/$T$7)*100) -> 71.212121 | Y14: =IF(V14>=50,"Y","N") -> Y | Z14: =IF(W14>=50,"Y","N") -> Y
B15: 5 | C15: =[5]Theory!A29 -> 2023-IT-05 | D15: =[5]Theory!B29 -> Alishba Saleem | E15: =[5]Theory!D29 -> 8 | F15: 7 | G15: 7 | H15: 2 | I15: =[5]Theory!E29 -> 16 | J15: =[5]Theory!H29 -> 8 | K15: =[5]Theory!F29 -> 8 | L15: 8 | M15: 8 | N15: 8 | O15: =[5]Theory!G29 -> 24 | P15: =E15+I15+J15+K15+O15 -> 64 | Q15: =[5]Theory!J29 -> B- | S15: =E15+F15+L15 -> 23 | T15: =G15+H15+K15+M15+J15+N15 -> 41 | V15: =((S15/$S$7)*100) -> 67.647059 | W15: =((T15/$T$7)*100) -> 62.121212 | Y15: =IF(V15>=50,"Y","N") -> Y | Z15: =IF(W15>=50,"Y","N") -> Y
B16: 6 | C16: =[5]Theory!A30 -> 2023-IT-06 | D16: =[5]Theory!B30 -> Mehak Asghar | E16: =[5]Theory!D30 -> 8 | F16: 8 | G16: 8 | H16: 4 | I16: =[5]Theory!E30 -> 20 | J16: =[5]Theory!H30 -> 8 | K16: =[5]Theory!F30 -> 8 | L16: 9 | M16: 10 | N16: 10 | O16: =[5]Theory!G30 -> 29 | P16: =E16+I16+J16+K16+O16 -> 73 | Q16: =[5]Theory!J30 -> B+ | S16: =E16+F16+L16 -> 25 | T16: =G16+H16+K16+M16+J16+N16 -> 48 | V16: =((S16/$S$7)*100) -> 73.529412 | W16: =((T16/$T$7)*100) -> 72.727273 | Y16: =IF(V16>=50,"Y","N") -> Y | Z16: =IF(W16>=50,"Y","N") -> Y
B17: 7 | C17: =[5]Theory!A31 -> 2023-IT-07 | D17: =[5]Theory!B31 -> Humaira Afzal | E17: =[5]Theory!D31 -> 9 | F17: 8 | G17: 9 | H17: 3 | I17: =[5]Theory!E31 -> 20 | J17: =[5]Theory!H31 -> 8 | K17: =[5]Theory!F31 -> 9 | L17: 12 | M17: 13 | N17: 7 | O17: =[5]Theory!G31 -> 32 | P17: =E17+I17+J17+K17+O17 -> 78 | Q17: =[5]Theory!J31 -> A- | S17: =E17+F17+L17 -> 29 | T17: =G17+H17+K17+M17+J17+N17 -> 49 | V17: =((S17/$S$7)*100) -> 85.294118 | W17: =((T17/$T$7)*100) -> 74.242424 | Y17: =IF(V17>=50,"Y","N") -> Y | Z17: =IF(W17>=50,"Y","N") -> Y
B18: 8 | C18: =[5]Theory!A32 -> 2023-IT-08 | D18: =[5]Theory!B32 -> Saleena Khan | E18: =[5]Theory!D32 -> 0 | F18: 0 | G18: 0 | H18: 0 | I18: =[5]Theory!E32 -> 0 | J18: =[5]Theory!H32 -> 0 | K18: =[5]Theory!F32 -> 0 | L18: 0 | M18: 0 | N18: 0 | O18: =[5]Theory!G32 -> 0 | P18: =E18+I18+J18+K18+O18 -> 0 | Q18: =[5]Theory!J32 -> F | S18: =E18+F18+L18 -> 0 | T18: =G18+H18+K18+M18+J18+N18 -> 0 | V18: =((S18/$S$7)*100) -> 0 | W18: =((T18/$T$7)*100) -> 0 | Y18: =IF(V18>=50,"Y","N") -> N | Z18: =IF(W18>=50,"Y","N") -> N
B19: 9 | C19: =[5]Theory!A33 -> 2023-IT-10 | D19: =[5]Theory!B33 -> Asad Ullah | E19: =[5]Theory!D33 -> 6 | F19: 7 | G19: 6 | H19: 2 | I19: =[5]Theory!E33 -> 15 | J19: =[5]Theory!H33 -> 7 | K19: =[5]Theory!F33 -> 9 | L19: 11 | M19: 10 | N19: 8 | O19: =[5]Theory!G33 -> 29 | P19: =E19+I19+J19+K19+O19 -> 66 | Q19: =[5]Theory!J33 -> B | S19: =E19+F19+L19 -> 24 | T19: =G19+H19+K19+M19+J19+N19 -> 42 | V19: =((S19/$S$7)*100) -> 70.588235 | W19: =((T19/$T$7)*100) -> 63.636364 | Y19: =IF(V19>=50,"Y","N") -> Y | Z19: =IF(W19>=50,"Y","N") -> Y
