Workbook

Sheet OBE Sheet
C1: MNS - UNIVERSITY OF ENGINEERING AND TECHNOLOGY MULTAN
C2: Department of Computer Science
C3: Program: | D3: BS Computer Science | H3: Semester: | J3: 3rd Semester
C4: Session: | D4: Fall 2023 Section-B (Morning) | J4: Fall 2024
C5: Course: | D5: Title (Code): Software Engineering (CS-234) | H5: Instructor: | J5: Mr. Abdul Basit
D6: Credit Hours: | E6: 3 Theory
A7: OBE Assessment | E7: CLO1 | F7: CLO2 | G7: CLO3 | H7: CLO4 | I7: CLO5 | J7: CLO6 | K7: CLO7 | L7: CLO8 | M7: CLO9 | N7: CLO10 | O7: Total | P7: PLO1 | Q7: PLO2 | R7: PLO3 | S7: PLO4 | T7: PLO5 | U7: PLO6 | V7: PLO7 | W7: PLO8 | X7: PLO9 | Y7: PLO10 | Z7: Total
E8: {=TRANSPOSE(_xlfn._xlws.FILTER('CLO & PLO'!K1:K10,'OBE Sheet'!E7='CLO & PLO'!A1))} -> 27 | F8: 25 | G8: 23 | H8: 25 | I8: 0 | J8: 0 | K8: 0 | L8: 0 | M8: 0 | N8: 0 | O8: =SUM(E8:N8) -> 100 | P8: {=TRANSPOSE( _xlfn._xlws.FILTER('CLO & PLO'!X1:X10,'CLO & PLO'!N1='OBE Sheet'!P7))} -> 0 | Q8: 75 | R8: 25 | S8: 0 | T8: 0 | U8: 0 | V8: 0 | W8: 0 | X8: 0 | Y8: 0 | Z8: =SUM(P8:X8) -> 100
A9: S# | B9: CMS ID | C9: Assessment Tool ―→ | E9: Quiz1 | H9: Mid | M9: QuizII | P9: Final | U9: C.P | X9: Total | Y9: PLO Assessment | AB9: PLO Achieved
C10: Marks | E10: 10 | G10: =SUM(C10:F10) -> 10 | H10: 7 | I10: 20 | J10: 3 | L10: =SUM(H10:K10) -> 30 | M10: 10 | O10: =SUM(M10:N10) -> 10 | P10: 10 | Q10: 20 | R10: 10 | T10: =SUM(P10:S10) -> 40 | U10: 5 | V10: 5 | W10: =SUM(U10:V10) -> 10 | X10: =G10+L10+O10+T10+W10 -> 100
C11: Target CLO | E11: CLO1 | G11: Total | H11: CLO1 | I11: CLO2 | J11: CLO3 | L11: Total | M11: CLO4 | O11: Total | P11: CLO1 | Q11: CLO3 | R11: CLO4 | T11: Total | U11: CLO2 | V11: CLO4 | W11: Total | Y11: PLO1 | Z11: PLO2 | AA11: PLO3 | AB11: =Y11 -> PLO1 | AC11: =Z11 -> PLO2 | AD11: =AA11 -> PLO3
C12: Registration No | D12: Target PLO | E12: PLO2 | H12: PLO2 | I12: PLO2 | J12: PLO2 | M12: PLO3 | P12: PLO2 | Q12: PLO2 | R12: PLO3 | U12: PLO2 | V12: PLO3 | Y12: {=IFERROR(_xlfn._xlws.FILTER(_xlfn.ANCHORARRAY(P8),Y11=$P$7:$Y$7),0)} -> 0 | Z12: {=IFERROR(_xlfn._xlws.FILTER(_xlfn.ANCHORARRAY(P8),Z11=$P$7:$Y$7),0)} -> 75 | AA12: {=IFERROR(_xlfn._xlws.FILTER(_xlfn.ANCHORARRAY(P8),AA11=$P$7:$Y$7),0)} -> 25 | AB12: {=IFERROR(_xlfn._xlws.FILTER(_xlfn.ANCHORARRAY(P8),AB11=$P$7:$Y$7),0)} -> 0 | AC12: {=IFERROR(_xlfn._xlws.FILTER(_xlfn.ANCHORARRAY(P8),AC11=$P$7:$Y$7),0)} -> 75 | AD12: {=IFERROR(_xlfn._xlws.FILTER(_xlfn.ANCHORARRAY(P8),AD11=$P$7:$Y$7),0)} -> 25
A13: 1 | B13: 917-2017 | C13: 2023-CS-02 | D13: Malaika khan | E13: 9 | G13: =SUM(C13:F13) -> 9 | H13: 3.5 | I13: 2 | J13: 2 | L13: =SUM(H13:K13) -> 7.5 | M13: 4 | O13: =SUM(M13:N13) -> 4 | P13: 8 | Q13: 5 | R13: 3 | T13: =SUM(P13:S13) -> 16 | U13: 5 | V13: 5 | W13: =SUM(U13:V13) -> 10 | X13: =SUM(G13+L13+O13+T13+W13) -> 46.5 | Y13: =SUMIF($E$12:$V$12,$Y$11,E13:V13) -> 0 | Z13: =SUMIF($E$12:$V$12,$Z$11,E13:V13) -> 34.5 | AA13: =SUMIF($E$12:$V$12,$AA$11,E13:V13) -> 12 | AB13: =IFERROR(IF(Y13/$Y$12*100>=50,"Y","N"),0) -> 0 | AC13: =IFERROR(IF(Z13/$Z$12*100>=50,"Y","N"),0) -> N | AD13: =IFERROR(IF(AA13/$AA$12*100>=50,"Y","N"),0) -> N
A14: 2 | B14: 918-2017 | C14: 2023-CS-04 | D14: Muskan Rana | E14: 8 | G14: =SUM(C14:F14) -> 8 | H14: 3 | I14: 8 | J14: 2 | L14: =SUM(H14:K14) -> 13 | M14: 7 | O14: =SUM(M14:N14) -> 7 | P14: 7 | Q14: 13 | R14: 5 | T14: =SUM(P14:S14) -> 25 | U14: 5 | V14: 5 | W14: =SUM(U14:V14) -> 10 | X14: =SUM(G14+L14+O14+T14+W14) -> 63 | Y14: =SUMIF($E$12:$V$12,$Y$11,E14:V14) -> 0 | Z14: =SUMIF($E$12:$V$12,$Z$11,E14:V14) -> 46 | AA14: =SUMIF($E$12:$V$12,$AA$11,E14:V14) -> 17 | AB14: =IFERROR(IF(Y14/$Y$12*100>=50,"Y","N"),0) -> 0 | AC14: =IFERROR(IF(Z14/$Z$12*100>=50,"Y","N"),0) -> Y | AD14: =IFERROR(IF(AA14/$AA$12*100>=50,"Y","N"),0) -> Y
A15: 3 | B15: 919-2017 | C15: 2023-CS-06 | D15: Fatima Batool | E15: 8 | G15: =SUM(C15:F15) -> 8 | H15: 2 | I15: 9 | J15: 1 | L15: =SUM(H15:K15) -> 12 | M15: 7 | O15: =SUM(M15:N15) -> 7 | P15: 7 | Q15: 14 | R15: 6 | T15: =SUM(P15:S15) -> 27 | U15: 5 | V15: 5 | W15: =SUM(U15:V15) -> 10 | X15: =SUM(G15+L15+O15+T15+W15) -> 64 | Y15: =SUMIF($E$12:$V$12,$Y$11,E15:V15) -> 0 | Z15: =SUMIF($E$12:$V$12,$Z$11,E15:V15) -> 46 | AA15: =SUMIF($E$12:$V$12,$AA$11,E15:V15) -> 18 | AB15: =IFERROR(IF(Y15/$Y$12*100>=50,"Y","N"),0) -> 0 | AC15: =IFERROR(IF(Z15/$Z$12*100>=50,"Y","N"),0) -> Y | AD15: =IFERROR(IF(AA15/$AA$12*100>=50,"Y","N"),0) -> Y
A16: 4 | B16: 921-2017 | C16: 2023-CS-08 | D16: Noor Fatima Khaleeq | E16: 7 | G16: =SUM(C16:F16) -> 7 | H16: 3 | I16: 8 | J16: 0 | L16: =SUM(H16:K16) -> 11 | M16: 7 | O16: =SUM(M16:N16) -> 7 | P16: 6 | Q16: 14 | R16: 7 | T16: =SUM(P16:S16) -> 27 | U16: 5 | V16: 5 | W16: =SUM(U16:V16) -> 10 | X16: =SUM(G16+L16+O16+T16+W16) -> 62 | Y16: =SUMIF($E$12:$V$12,$Y$11,E16:V16) -> 0 | Z16: =SUMIF($E$12:$V$12,$Z$11,E16:V16) -> 43 | AA16: =SUMIF($E$12:$V$12,$AA$11,E16:V16) -> 19 | AB16: =IFERROR(IF(Y16/$Y$12*100>=50,"Y","N"),0) -> 0 | AC16: =IFERROR(IF(Z16/$Z$12*100>=50,"Y","N"),0) -> Y | AD16: =IFERROR(IF(AA16/$AA$12*100>=50,"Y","N"),0) -> Y
A17: 5 | B17: 922-2017 | C17: 2023-CS-10 | D17: Manahil Raees | E17: 10 | G17: =SUM(C17:F17) -> 10 | H17: 5 | I17: 16 | J17: 3 | L17: =SUM(H17:K17) -> 24 | M17: 9 | O17: =SUM(M17:N17) -> 9 | P17: 7 | Q17: 15 | R17: 5 | T17: =SUM(P17:S17) -> 27 | U17: 5 | V17: 5 | W17: =SUM(U17:V17) -> 10 | X17: =SUM(G17+L17+O17+T17+W17) -> 80 | Y17: =SUMIF($E$12:$V$12,$Y$11,E17:V17) -> 0 | Z17: =SUMIF($E$12:$V$12,$Z$11,E17:V17) -> 61 | AA17: =SUMIF($E$12:$V$12,$AA$11,E17:V17) -> 19 | AB17: =IFERROR(IF(Y17/$Y$12*100>=50,"Y","N"),0) -> 0 | AC17: =IFERROR(IF(Z17/$Z$12*100>=50,"Y","N"),0) -> Y | AD17: =IFERROR(IF(AA17/$AA$12*100>=50,"Y","N"),0) -> Y
A18: 6 | B18: 923-2017 | C18: 2023-CS-12 | D18: Ghanwa Malik | E18: 8 | G18: =SUM(C18:F18) -> 8 | H18: 3 | I18: 9 | J18: 1 | L18: =SUM(H18:K18) -> 13 | M18: 7 | O18: =SUM(M18:N18) -> 7 | P18: 7 | Q18: 6 | R18: 7 | T18: =SUM(P18:S18) -> 20 | U18: 5 | V18: 5 | W18: =SUM(U18:V18) -> 10 | X18: =SUM(G18+L18+O18+T18+W18) -> 58 | Y18: =SUMIF($E$12:$V$12,$Y$11,E18:V18) -> 0 | Z18: =SUMIF($E$12:$V$12,$Z$11,E18:V18) -> 39 | AA18: =SUMIF($E$12:$V$12,$AA$11,E18:V18) -> 19 | AB18: =IFERROR(IF(Y18/$Y$12*100>=50,"Y","N"),0) -> 0 | AC18: =IFERROR(IF(Z18/$Z$12*100>=50,"Y","N"),0) -> Y | AD18: =IFERROR(IF(AA18/$AA$12*100>=50,"Y","N"),0) -> Y
A19: 7 | B19: 1144-2017 | C19: 2023-CS-14 | D19: Zarwa Imran | E19: 9 | G19: =SUM(C19:F19) -> 9 | H19: 6 | I19: 13 | J19: 3 | L19: =SUM(H19:K19) -> 22 | M19: 8 | O19: =SUM(M19:N19) -> 8 | P19: 6 | Q19: 14 | R19: 7 | T19: =SUM(P19:S19) -> 27 | U19: 5 | V19: 5 | W19: =SUM(U19:V19) -> 10 | X19: =SUM(G19+L19+O19+T19+W19) -> 76 | Y19: =SUMIF($E$12:$V$12,$Y$11,E19:V19) -> 0 | Z19: =SUMIF($E$12:$V$12,$Z$11,E19:V19) -> 56 | AA19: =SUMIF($E$12:$V$12,$AA$11,E19:V19) -> 20 | AB19: =IFERROR(IF(Y19/$Y$12*100>=50,"Y","N"),0) -> 0 | AC19: =IFERROR(IF(Z19/$Z$12*100>=50,"Y","N"),0) -> Y | AD19: =IFERROR(IF(AA19/$AA$12*100>=50,"Y","N"),0) -> Y
A20: 10 | B20: 932-2017 | C20: 2023-CS-16 | D20: Saira Aziz | E20: 7 | G20: =SUM(C20:F20) -> 7 | H20: 6 | I20: 15 | J20: 3 | L20: =SUM(H20:K20) -> 24 | M20: 5 | O20: 7 | P20: 7 | Q20: 16 | R20: 7 | T20: =SUM(P20:S20) -> 30 | U20: 4 | V20: 3 | W20: =SUM(U20:V20) -> 7 | X20: =SUM(G20+L20+O20+T20+W20) -> 75 | Y20: =SUMIF($E$12:$V$12,$Y$11,E20:V20) -> 0 | Z20: =SUMIF($E$12:$V$12,$Z$11,E20:V20) -> 58 | AA20: =SUMIF($E$12:$V$12,$AA$11,E20:V20) -> 15 | AB20: =IFERROR(IF(Y20/$Y$12*100>=50,"Y","N"),0) -> 0 | AC20: =IFERROR(IF(Z20/$Z$12*100>=50,"Y","N"),0) -> Y | AD20: =IFERROR(IF(AA20/$AA$12*100>=50,"Y","N"),0) -> Y
A21: 11 | B21: 1169-2017 | C21: 2023-CS-18 | D21: Zahra Aslam | E21: 6 | G21: =SUM(C21:F21) -> 6 | H21: 6 | I21: 14 | J21: 1 | L21: =SUM(H21:K21) -> 21 | M21: 7 | O21: =SUM(M21:N21) -> 7 | P21: 4 | Q21: 16 | R21: 8 | T21: =SUM(P21:S21) -> 28 | U21: 4 | V21: 5 | W21: =SUM(U21:V21) -> 9 | X21: =SUM(G21+L21+O21+T21+W21) -> 71 | Y21: =SUMIF($E$12:$V$12,$Y$11,E21:V21) -> 0 | Z21: =SUMIF($E$12:$V$12,$Z$11,E21:V21) -> 51 | AA21: =SUMIF($E$12:$V$12,$AA$11,E21:V21) -> 20 | AB21: =IFERROR(IF(Y21/$Y$12*100>=50,"Y","N"),0) -> 0 | AC21: =IFERROR(IF(Z21/$Z$12*100>=50,"Y","N"),0) -> Y | AD21: =IFERROR(IF(AA21/$AA$12*100>=50,"Y","N"),0) -> Y
A22: 12 | B22: 1068-2017 | C22: 2023-CS-20 | D22: Uswa farooq | E22: 8 | G22: =SUM(C22:F22) -> 8 | H22: 7 | I22: 7 | J22: 2 | L22: =SUM(H22:K22) -> 16 | M22: 8 | O22: =SUM(M22:N22) -> 8 | P22: 7 | Q22: 12 | R22: 6 | T22: =SUM(P22:S22) -> 25 | U22: 5 | V22: 5 | W22: =SUM(U22:V22) -> 10 | X22: =SUM(G22+L22+O22+T22+W22) -> 67 | Y22: =SUMIF($E$12:$V$12,$Y$11,E22:V22) -> 0 | Z22: =SUMIF($E$12:$V$12,$Z$11,E22:V22) -> 48 | AA22: =SUMIF($E$12:$V$12,$AA$11,E22:V22) -> 19 | AB22: =IFERROR(IF(Y22/$Y$12*100>=50,"Y","N"),0) -> 0 | AC22: =IFERROR(IF(Z22/$Z$12*100>=50,"Y","N"),0) -> Y | AD22: =IFERROR(IF(AA22/$AA$12*100>=50,"Y","N"),0) -> Y
A23: 13 | B23: 933-2017 | C23: 2023-CS-22 | D23: Rimsha Nazeer | E23: 9 | G23: =SUM(C23:F23) -> 9 | H23: 7 | I23: 12 | J23: 3 | L23: =SUM(H23:K23) -> 22 | M23: 9 | O23: =SUM(M23:N23) -> 9 | P23: 9 | Q23: 16 | R23: 7 | T23: =SUM(P23:S23) -> 32 | U23: 5 | V23: 5 | W23: =SUM(U23:V23) -> 10 | X23: =SUM(G23+L23+O23+T23+W23) -> 82 | Y23: =SUMIF($E$12:$V$12,$Y$11,E23:V23) -> 0 | Z23: =SUMIF($E$12:$V$12,$Z$11,E23:V23) -> 61 | AA23: =SUMIF($E$12:$V$12,$AA$11,E23:V23) -> 21 | AB23: =IFERROR(IF(Y23/$Y$12*100>=50,"Y","N"),0) -> 0 | AC23: =IFERROR(IF(Z23/$Z$12*100>=50,"Y","N"),0) -> Y | AD23: =IFERROR(IF(AA23/$AA$12*100>=50,"Y","N"),0) -> Y
A24: 14 | B24: 934-2017 | C24: 2023-CS-24 | D24: Fareed Ahmed | G24: =SUM(C24:F24) -> 0 | L24: =SUM(H24:K24) -> 0 | O24: =SUM(M24:N24) -> 0 | T24: =SUM(P24:S24) -> 0 | W24: =SUM(U24:V24) -> 0 | X24: =SUM(G24+L24+O24+T24+W24) -> 0 | Y24: =SUMIF($E$12:$V$12,$Y$11,E24:V24) -> 0 | Z24: =SUMIF($E$12:$V$12,$Z$11,E24:V24) -> 0 | AA24: =SUMIF($E$12:$V$12,$AA$11,E24:V24) -> 0 | AB24: =IFERROR(IF(Y24/$Y$12*100>=50,"Y","N"),0) -> 0 | AC24: =IFERROR(IF(Z24/$Z$12*100>=50,"Y","N"),0) -> N | AD24: =IFERROR(IF(AA24/$AA$12*100>=50,"Y","N"),0) -> N
A25: 16 | B25: 938-2017 | C25: 2023-CS-26 | D25: Muhammad Adnan Nasir | G25: =SUM(C25:F25) -> 0 | L25: =SUM(H25:K25) -> 0 | O25: =SUM(M25:N25) -> 0 | T25: =SUM(P25:S25) -> 0 | W25: =SUM(U25:V25) -> 0 | X25: =SUM(G25+L25+O25+T25+W25) -> 0 | Y25: =SUMIF($E$12:$V$12,$Y$11,E25:V25) -> 0 | Z25: =SUMIF($E$12:$V$12,$Z$11,E25:V25) -> 0 | AA25: =SUMIF($E$12:$V$12,$AA$11,E25:V25) -> 0 | AB25: =IFERROR(IF(Y25/$Y$12*100>=50,"Y","N"),0) -> 0 | AC25: =IFERROR(IF(Z25/$Z$12*100>=50,"Y","N"),0) -> N | AD25: =IFERROR(IF(AA25/$AA$12*100>=50,"Y","N"),0) -> N
A26: 17 | B26: 1584-2017 | C26: 2023-CS-28 | D26: Ahmed raza | E26: 7 | G26: =SUM(C26:F26) -> 7 | H26: 5 | I26: 7 | J26: 3 | L26: =SUM(H26:K26) -> 15 | M26: 9 | O26: =SUM(M26:N26) -> 9 | P26: 7 | Q26: 11 | R26: 7 | T26: =SUM(P26:S26) -> 25 | U26: 5 | V26: 5 | W26: =SUM(U26:V26) -> 10 | X26: =SUM(G26+L26+O26+T26+W26) -> 66 | Y26: =SUMIF($E$12:$V$12,$Y$11,E26:V26) -> 0 | Z26: =SUMIF($E$12:$V$12,$Z$11,E26:V26) -> 45 | AA26: =SUMIF($E$12:$V$12,$AA$11,E26:V26) -> 21 | AB26: =IFERROR(IF(Y26/$Y$12*100>=50,"Y","N"),0) -> 0 | AC26: =IFERROR(IF(Z26/$Z$12*100>=50,"Y","N"),0) -> Y | AD26: =IFERROR(IF(AA26/$AA$12*100>=50,"Y","N"),0) -> Y
A27: 18 | B27: 1159-2017 | C27: 2023-CS-30 | D27: Muhammad Rashid | E27: 7 | G27: =SUM(C27:F27) -> 7 | H27: 3 | I27: 5 | J27: 3 | L27: =SUM(H27:K27) -> 11 | M27: 8 | O27: =SUM(M27:N27) -> 8 | P27: 5 | Q27: 10 | R27: 4 | T27: =SUM(P27:S27) -> 19 | U27: 5 | V27: 5 | W27: =SUM(U27:V27) -> 10 | X27: =SUM(G27+L27+O27+T27+W27) -> 55 | Y27: =SUMIF($E$12:$V$12,$Y$11,E27:V27) -> 0 | Z27: =SUMIF($E$12:$V$12,$Z$11,E27:V27) -> 38 | AA27: =SUMIF($E$12:$V$12,$AA$11,E27:V27) -> 17 | AB27: =IFERROR(IF(Y27/$Y$12*100>=50,"Y","N"),0) -> 0 | AC27: =IFERROR(IF(Z27/$Z$12*100>=50,"Y","N"),0) -> Y | AD27: =IFERROR(IF(AA27/$AA$12*100>=50,"Y","N"),0) -> Y
A28: 19 | B28: 939-2017 | C28: 2023-CS-32 | D28: Muhammad Zubair | G28: =SUM(C28:F28) -> 0 | L28: =SUM(H28:K28) -> 0 | O28: =SUM(M28:N28) -> 0 | T28: =SUM(P28:S28) -> 0 | W28: =SUM(U28:V28) -> 0 | X28: =SUM(G28+L28+O28+T28+W28) -> 0 | Y28: =SUMIF($E$12:$V$12,$Y$11,E28:V28) -> 0 | Z28: =SUMIF($E$12:$V$12,$Z$11,E28:V28) -> 0 | AA28: =SUMIF($E$12:$V$12,$AA$11,E28:V28) -> 0 | AB28: =IFERROR(IF(Y28/$Y$12*100>=50,"Y","N"),0) -> 0 | AC28: =IFERROR(IF(Z28/$Z$12*100>=50,"Y","N"),0) -> N | AD28: =IFERROR(IF(AA28/$AA$12*100>=50,"Y","N"),0) -> N
A29: 21 | B29: 941-2017 | C29: 2023-CS-34 | D29: Muhammad Waqas Inam | G29: =SUM(C29:F29) -> 0 | L29: =SUM(H29:K29) -> 0 | O29: =SUM(M29:N29) -> 0 | T29: =SUM(P29:S29) -> 0 | W29: =SUM(U29:V29) -> 0 | X29: =SUM(G29+L29+O29+T29+W29) -> 0 | Y29: =SUMIF($E$12:$V$12,$Y$11,E29:V29) -> 0 | Z29: =SUMIF($E$12:$V$12,$Z$11,E29:V29) -> 0 | AA29: =SUMIF($E$12:$V$12,$AA$11,E29:V29) -> 0 | AB29: =IFERROR(IF(Y29/$Y$12*100>=50,"Y","N"),0) -> 0 | AC29: =IFERROR(IF(Z29/$Z$12*100>=50,"Y","N"),0) -> N | AD29: =IFERROR(IF(AA29/$AA$12*100>=50,"Y","N"),0) -> N
A30: 22 | B30: 1156-2017 | C30: 2023-CS-36 | D30: Muhammad Nouman Yousaf | E30: 9 | G30: =SUM(C30:F30) -> 9 | H30: 2 | I30: 3 | J30: 0 | L30: =SUM(H30:K30) -> 5 | M30: 9 | O30: =SUM(M30:N30) -> 9 | P30: 6 | Q30: 11 | R30: 5 | T30: =SUM(P30:S30) -> 22 | U30: 5 | V30: 5 | W30: =SUM(U30:V30) -> 10 | X30: =SUM(G30+L30+O30+T30+W30) -> 55 | Y30: =SUMIF($E$12:$V$12,$Y$11,E30:V30) -> 0 | Z30: =SUMIF($E$12:$V$12,$Z$11,E30:V30) -> 36 | AA30: =SUMIF($E$12:$V$12,$AA$11,E30:V30) -> 19 | AB30: =IFERROR(IF(Y30/$Y$12*100>=50,"Y","N"),0) -> 0 | AC30: =IFERROR(IF(Z30/$Z$12*100>=50,"Y","N"),0) -> N | AD30: =IFERROR(IF(AA30/$AA$12*100>=50,"Y","N"),0) -> Y
A31: 23 | B31: 946-2017 | C31: 2023-CS-38 | D31: Muhammad Fahad Khalid | G31: =SUM(C31:F31) -> 0 | L31: =SUM(H31:K31) -> 0 | O31: =SUM(M31:N31) -> 0 | T31: =SUM(P31:S31) -> 0 | W31: =SUM(U31:V31) -> 0 | X31: =SUM(G31+L31+O31+T31+W31) -> 0 | Y31: =SUMIF($E$12:$V$12,$Y$11,E31:V31) -> 0 | Z31: =SUMIF($E$12:$V$12,$Z$11,E31:V31) -> 0 | AA31: =SUMIF($E$12:$V$12,$AA$11,E31:V31) -> 0 | AB31: =IFERROR(IF(Y31/$Y$12*100>=50,"Y","N"),0) -> 0 | AC31: =IFERROR(IF(Z31/$Z$12*100>=50,"Y","N"),0) -> N | AD31: =IFERROR(IF(AA31/$AA$12*100>=50,"Y","N"),0) -> N
A32: 24 | B32: 1067-2017 | C32: 2023-CS-40 | D32: Muhammad Umair | E32: 4 | G32: =SUM(C32:F32) -> 4 | H32: 5 | I32: 8 | J32: 1 | L32: =SUM(H32:K32) -> 14 | M32: 8 | O32: =SUM(M32:N32) -> 8 | P32: 8 | Q32: 12 | R32: 6 | T32: =SUM(P32:S32) -> 26 | U32: 5 | V32: 5 | W32: =SUM(U32:V32) -> 10 | X32: =SUM(G32+L32+O32+T32+W32) -> 62 | Y32: =SUMIF($E$12:$V$12,$Y$11,E32:V32) -> 0 | Z32: =SUMIF($E$12:$V$12,$Z$11,E32:V32) -> 43 | AA32: =SUMIF($E$12:$V$12,$AA$11,E32:V32) -> 19 | AB32: =IFERROR(IF(Y32/$Y$12*100>=50,"Y","N"),0) -> 0 | AC32: =IFERROR(IF(Z32/$Z$12*100>=50,"Y","N"),0) -> Y | AD32: =IFERROR(IF(AA32/$AA$12*100>=50,"Y","N"),0) -> Y
A33: 25 | B33: 950-2017 | C33: 2023-CS-42 | D33: Muhammad Anas | E33: 7 | G33: =SUM(C33:F33) -> 7 | H33: 5 | I33: 9 | J33: 3 | L33: =SUM(H33:K33) -> 17 | M33: 7 | O33: =SUM(M33:N33) -> 7 | P33: 6 | Q33: 14 | R33: 8 | T33: =SUM(P33:S33) -> 28 | U33: 5 | V33: 5 | W33: =SUM(U33:V33) -> 10 | X33: =SUM(G33+L33+O33+T33+W33) -> 69 | Y33: =SUMIF($E$12:$V$12,$Y$11,E33:V33) -> 0 | Z33: =SUMIF($E$12:$V$12,$Z$11,E33:V33) -> 49 | AA33: =SUMIF($E$12:$V$12,$AA$11,E33:V33) -> 20 | AB33: =IFERROR(IF(Y33/$Y$12*100>=50,"Y","N"),0) -> 0 | AC33: =IFERROR(IF(Z33/$Z$12*100>=50,"Y","N"),0) -> Y | AD33: =IFERROR(IF(AA33/$AA$12*100>=50,"Y","N"),0) -> Y
A34: 27 | B34: 953-2017 | C34: 2023-CS-44 | D34: Shoaib Ahmed | E34: 8 | G34: =SUM(C34:F34) -> 8 | H34: 6 | I34: 11 | J34: 3 | L34: =SUM(H34:K34) -> 20 | M34: 8 | O34: =SUM(M34:N34) -> 8 | P34: 4 | Q34: 12 | R34: 8 | T34: =SUM(P34:S34) -> 24 | U34: 5 | V34: 5 | W34: =SUM(U34:V34) -> 10 | X34: =SUM(G34+L34+O34+T34+W34) -> 70 | Y34: =SUMIF($E$12:$V$12,$Y$11,E34:V34) -> 0 | Z34: =SUMIF($E$12:$V$12,$Z$11,E34:V34) -> 49 | AA34: =SUMIF($E$12:$V$12,$AA$11,E34:V34) -> 21 | AB34: =IFERROR(IF(Y34/$Y$12*100>=50,"Y","N"),0) -> 0 | AC34: =IFERROR(IF(Z34/$Z$12*100>=50,"Y","N"),0) -> Y | AD34: =IFERROR(IF(AA34/$AA$12*100>=50,"Y","N"),0) -> Y
A35: 28 | B35: 954-2017 | C35: 2023-CS-46 | D35: Muhammad Ali Huzaifa | G35: =SUM(C35:F35) -> 0 | L35: =SUM(H35:K35) -> 0 | O35: =SUM(M35:N35) -> 0 | T35: =SUM(P35:S35) -> 0 | W35: =SUM(U35:V35) -> 0 | X35: =SUM(G35+L35+O35+T35+W35) -> 0 | Y35: =SUMIF($E$12:$V$12,$Y$11,E35:V35) -> 0 | Z35: =SUMIF($E$12:$V$12,$Z$11,E35:V35) -> 0 | AA35: =SUMIF($E$12:$V$12,$AA$11,E35:V35) -> 0 | AB35: =IFERROR(IF(Y35/$Y$12*100>=50,"Y","N"),0) -> 0 | AC35: =IFERROR(IF(Z35/$Z$12*100>=50,"Y","N"),0) -> N | AD35: =IFERROR(IF(AA35/$AA$12*100>=50,"Y","N"),0) -> N
C36: 2023-CS-48 | D36: Muhammad Samad Amir | E36: 7 | G36: =SUM(C36:F36) -> 7 | H36: 3 | I36: 5 | J36: 2 | L36: =SUM(H36:K36) -> 10 | M36: 7 | O36: =SUM(M36:N36) -> 7 | P36: 6 | Q36: 10 | R36: 3 | T36: =SUM(P36:S36) -> 19 | U36: 5 | V36: 5 | W36: =SUM(U36:V36) -> 10 | X36: =SUM(G36+L36+O36+T36+W36) -> 53 | Y36: =SUMIF($E$12:$V$12,$Y$11,E36:V36) -> 0 | Z36: =SUMIF($E$12:$V$12,$Z$11,E36:V36) -> 38 | AA36: =SUMIF($E$12:$V$12,$AA$11,E36:V36) -> 15 | AB36: =IFERROR(IF(Y36/$Y$12*100>=50,"Y","N"),0) -> 0 | AC36: =IFERROR(IF(Z36/$Z$12*100>=50,"Y","N"),0) -> Y | AD36: =IFERROR(IF(AA36/$AA$12*100>=50,"Y","N"),0) -> Y
C37: 2023-CS-50 | D37: Muhammad Kamran Iqbal | E37: 5 | G37: =SUM(C37:F37) -> 5 | H37: 7 | I37: 14 | J37: 2 | L37: =SUM(H37:K37) -> 23 | M37: 8 | O37: =SUM(M37:N37) -> 8 | P37: 6 | Q37: 13 | R37: 6 | T37: =SUM(P37:S37) -> 25 | U37: 5 | V37: 5 | W37: =SUM(U37:V37) -> 10 | X37: =SUM(G37+L37+O37+T37+W37) -> 71 | Y37: =SUMIF($E$12:$V$12,$Y$11,E37:V37) -> 0 | Z37: =SUMIF($E$12:$V$12,$Z$11,E37:V37) -> 52 | AA37: =SUMIF($E$12:$V$12,$AA$11,E37:V37) -> 19 | AB37: =IFERROR(IF(Y37/$Y$12*100>=50,"Y","N"),0) -> 0 | AC37: =IFERROR(IF(Z37/$Z$12*100>=50,"Y","N"),0) -> Y | AD37: =IFERROR(IF(AA37/$AA$12*100>=50,"Y","N"),0) -> Y
C38: 2023-CS-52 | D38: Mirza Muhammad Umar | E38: 4 | G38: =SUM(C38:F38) -> 4 | H38: 5 | I38: 11 | J38: 3 | L38: =SUM(H38:K38) -> 19 | M38: 6 | O38: =SUM(M38:N38) -> 6 | P38: 7 | Q38: 13 | R38: 9 | T38: =SUM(P38:S38) -> 29 | U38: 5 | V38: 5 | W38: =SUM(U38:V38) -> 10 | X38: =SUM(G38+L38+O38+T38+W38) -> 68 | Y38: =SUMIF($E$12:$V$12,$Y$11,E38:V38) -> 0 | Z38: =SUMIF($E$12:$V$12,$Z$11,E38:V38) -> 48 | AA38: =SUMIF($E$12:$V$12,$AA$11,E38:V38) -> 20 | AB38: =IFERROR(IF(Y38/$Y$12*100>=50,"Y","N"),0) -> 0 | AC38: =IFERROR(IF(Z38/$Z$12*100>=50,"Y","N"),0) -> Y | AD38: =IFERROR(IF(AA38/$AA$12*100>=50,"Y","N"),0) -> Y
C39: 2023-CS-54 | D39: Muhammad Usman | E39: 7 | G39: =SUM(C39:F39) -> 7 | H39: 6 | I39: 10 | J39: 1 | L39: =SUM(H39:K39) -> 17 | M39: 7 | O39: =SUM(M39:N39) -> 7 | P39: 7 | Q39: 13 | R39: 5 | T39: =SUM(P39:S39) -> 25 | U39: 5 | V39: 5 | W39: =SUM(U39:V39) -> 10 | X39: =SUM(G39+L39+O39+T39+W39) -> 66 | Y39: =SUMIF($E$12:$V$12,$Y$11,E39:V39) -> 0 | Z39: =SUMIF($E$12:$V$12,$Z$11,E39:V39) -> 49 | AA39: =SUMIF($E$12:$V$12,$AA$11,E39:V39) -> 17 | AB39: =IFERROR(IF(Y39/$Y$12*100>=50,"Y","N"),0) -> 0 | AC39: =IFERROR(IF(Z39/$Z$12*100>=50,"Y","N"),0) -> Y | AD39: =IFERROR(IF(AA39/$AA$12*100>=50,"Y","N"),0) -> Y
C40: 2023-CS-56 | D40: Muhammad Arshad | E40: 7 | G40: =SUM(C40:F40) -> 7 | H40: 6 | I40: 16 | J40: 3 | L40: =SUM(H40:K40) -> 25 | M40: 8 | O40: =SUM(M40:N40) -> 8 | P40: 7 | Q40: 13 | R40: 7 | T40: =SUM(P40:S40) -> 27 | U40: 5 | V40: 5 | W40: =SUM(U40:V40) -> 10 | X40: =SUM(G40+L40+O40+T40+W40) -> 77 | Y40: =SUMIF($E$12:$V$12,$Y$11,E40:V40) -> 0 | Z40: =SUMIF($E$12:$V$12,$Z$11,E40:V40) -> 57 | AA40: =SUMIF($E$12:$V$12,$AA$11,E40:V40) -> 20 | AB40: =IFERROR(IF(Y40/$Y$12*100>=50,"Y","N"),0) -> 0 | AC40: =IFERROR(IF(Z40/$Z$12*100>=50,"Y","N"),0) -> Y | AD40: =IFERROR(IF(AA40/$AA$12*100>=50,"Y","N"),0) -> Y
...

Sheet Result Sheet
A1: MNS - UNIVERSITY OF ENGINEERING AND TECHNOLOGY MULTAN
A2: Department of Computer Science
A3: Program: | B3: ='OBE Sheet'!D3 -> BS Computer Science | F3: Semester: | H3: ='OBE Sheet'!J3 -> 3rd Semester
A4: Session: | B4: ='OBE Sheet'!D4 -> Fall 2023 Section-B (Morning) | H4: ='OBE Sheet'!J4 -> Fall 2024
A5: Course: | B5: ='OBE Sheet'!D5 -> Title (Code): Software Engineering (CS-234) | F5: Instructor: | H5: ='OBE Sheet'!J5 -> Mr. Abdul Basit
B6: Credit Hours: | C6: ='OBE Sheet'!E6 -> 3 Theory
H8: Criterea | I8: Grade | J8: Students
H9: 0 | I9: F | J9: =COUNTIF($J$25:$J$73,I9) -> 6
H10: 33 | I10: D | J10: =COUNTIF($J$25:$J$73,I10) -> 0
H11: 34 | I11: D+ | J11: =COUNTIF($J$25:$J$73,I11) -> 0
H12: 36 | I12: C- | J12: =COUNTIF($J$25:$J$73,I12) -> 0
H13: 38 | I13: C | J13: =COUNTIF($J$25:$J$73,I13) -> 0
H14: 40 | I14: C+ | J14: =COUNTIF($J$25:$J$73,I14) -> 1
H15: 45 | I15: B- | J15: =COUNTIF($J$25:$J$73,I15) -> 2
H16: 50 | I16: B | J16: =COUNTIF($J$25:$J$73,I16) -> 9
H17: 60 | I17: B+ | J17: =COUNTIF($J$25:$J$73,I17) -> 13
H18: 70 | I18: A- | J18: =COUNTIF($J$25:$J$73,I18) -> 10
H19: 78 | I19: A | J19: =COUNTIF($J$25:$J$73,I19) -> 2
H20: 85 | I20: A+ | J20: =COUNTIF($J$25:$J$73,I20) -> 0
H21: Total Students: | J21: =SUM(J9:J20) -> 43
A23: Registration No | B23: Name of Students | D23: Quiz 1 | E23: Mid | F23: Quiz 2 | G23: Final | H23: C.P | I23: Total | J23: Grade
A24: Weightage: | D24: 10 | E24: 30 | F24: 10 | G24: 40 | H24: 10 | I24: =SUM(D25:H25) -> 100
A25: Total Marks: | D25: 10 | E25: 30 | F25: 10 | G25: 40 | H25: 10 | I25: 100
A26: ='OBE Sheet'!C13 -> 2023-CS-02 | B26: ='OBE Sheet'!D13 -> Malaika khan | D26: ='OBE Sheet'!G13 -> 9 | E26: ='OBE Sheet'!L13 -> 7.5 | F26: ='OBE Sheet'!O13 -> 4 | G26: ='OBE Sheet'!T13 -> 16 | H26: ='OBE Sheet'!W13 -> 10 | I26: =SUM(D26:H26) -> 46.5 | J26: =VLOOKUP(I26,$H$9:$I$20,2,TRUE) -> B-
A27: ='OBE Sheet'!C14 -> 2023-CS-04 | B27: ='OBE Sheet'!D14 -> Muskan Rana | D27: ='OBE Sheet'!G14 -> 8 | E27: ='OBE Sheet'!L14 -> 13 | F27: ='OBE Sheet'!O14 -> 7 | G27: ='OBE Sheet'!T14 -> 25 | H27: ='OBE Sheet'!W14 -> 10 | I27: =SUM(D27:H27) -> 63 | J27: =VLOOKUP(I27,$H$9:$I$20,2,TRUE) -> B+
A28: ='OBE Sheet'!C15 -> 2023-CS-06 | B28: ='OBE Sheet'!D15 -> Fatima Batool | D28: ='OBE Sheet'!G15 -> 8 | E28: ='OBE Sheet'!L15 -> 12 | F28: ='OBE Sheet'!O15 -> 7 | G28: ='OBE Sheet'!T15 -> 27 | H28: ='OBE Sheet'!W15 -> 10 | I28: =SUM(D28:H28) -> 64 | J28: =VLOOKUP(I28,$H$9:$I$20,2,TRUE) -> B+
A29: ='OBE Sheet'!C16 -> 2023-CS-08 | B29: ='OBE Sheet'!D16 -> Noor Fatima Khaleeq | D29: ='OBE Sheet'!G16 -> 7 | E29: ='OBE Sheet'!L16 -> 11 | F29: ='OBE Sheet'!O16 -> 7 | G29: ='OBE Sheet'!T16 -> 27 | H29: ='OBE Sheet'!W16 -> 10 | I29: =SUM(D29:H29) -> 62 | J29: =VLOOKUP(I29,$H$9:$I$20,2,TRUE) -> B+
A30: ='OBE Sheet'!C17 -> 2023-CS-10 | B30: ='OBE Sheet'!D17 -> Manahil Raees | D30: ='OBE Sheet'!G17 -> 10 | E30: ='OBE Sheet'!L17 -> 24 | F30: ='OBE Sheet'!O17 -> 9 | G30: ='OBE Sheet'!T17 -> 27 | H30: ='OBE Sheet'!W17 -> 10 | I30: =SUM(D30:H30) -> 80 | J30: =VLOOKUP(I30,$H$9:$I$20,2,TRUE) -> A
A31: ='OBE Sheet'!C18 -> 2023-CS-12 | B31: ='OBE Sheet'!D18 -> Ghanwa Malik | D31: ='OBE Sheet'!G18 -> 8 | E31: ='OBE Sheet'!L18 -> 13 | F31: ='OBE Sheet'!O18 -> 7 | G31: ='OBE Sheet'!T18 -> 20 | H31: ='OBE Sheet'!W18 -> 10 | I31: =SUM(D31:H31) -> 58 | J31: =VLOOKUP(I31,$H$9:$I$20,2,TRUE) -> B
A32: ='OBE Sheet'!C19 -> 2023-CS-14 | B32: ='OBE Sheet'!D19 -> Zarwa Imran | D32: ='OBE Sheet'!G19 -> 9 | E32: ='OBE Sheet'!L19 -> 22 | F32: ='OBE Sheet'!O19 -> 8 | G32: ='OBE Sheet'!T19 -> 27 | H32: ='OBE Sheet'!W19 -> 10 | I32: =SUM(D32:H32) -> 76 | J32: =VLOOKUP(I32,$H$9:$I$20,2,TRUE) -> A-
A33: ='OBE Sheet'!C20 -> 2023-CS-16 | B33: ='OBE Sheet'!D20 -> Saira Aziz | D33: ='OBE Sheet'!G20 -> 7 | E33: ='OBE Sheet'!L20 -> 24 | F33: ='OBE Sheet'!O20 -> 7 | G33: ='OBE Sheet'!T20 -> 30 | H33: ='OBE Sheet'!W20 -> 7 | I33: =SUM(D33:H33) -> 75 | J33: =VLOOKUP(I33,$H$9:$I$20,2,TRUE) -> A-
A34: ='OBE Sheet'!C21 -> 2023-CS-18 | B34: ='OBE Sheet'!D21 -> Zahra Aslam | D34: ='OBE Sheet'!G21 -> 6 | E34: ='OBE Sheet'!L21 -> 21 | F34: ='OBE Sheet'!O21 -> 7 | G34: ='OBE Sheet'!T21 -> 28 | H34: ='OBE Sheet'!W21 -> 9 | I34: =SUM(D34:H34) -> 71 | J34: =VLOOKUP(I34,$H$9:$I$20,2,TRUE) -> A-
A35: ='OBE Sheet'!C22 -> 2023-CS-20 | B35: ='OBE Sheet'!D22 -> Uswa farooq | D35: ='OBE Sheet'!G22 -> 8 | E35: ='OBE Sheet'!L22 -> 16 | F35: ='OBE Sheet'!O22 -> 8 | G35: ='OBE Sheet'!T22 -> 25 | H35: ='OBE Sheet'!W22 -> 10 | I35: =SUM(D35:H35) -> 67 | J35: =VLOOKUP(I35,$H$9:$I$20,2,TRUE) -> B+
A36: ='OBE Sheet'!C23 -> 2023-CS-22 | B36: ='OBE Sheet'!D23 -> Rimsha Nazeer | D36: ='OBE Sheet'!G23 -> 9 | E36: ='OBE Sheet'!L23 -> 22 | F36: ='OBE Sheet'!O23 -> 9 | G36: ='OBE Sheet'!T23 -> 32 | H36: ='OBE Sheet'!W23 -> 10 | I36: =SUM(D36:H36) -> 82 | J36: =VLOOKUP(I36,$H$9:$I$20,2,TRUE) -> A
A37: ='OBE Sheet'!C24 -> 2023-CS-24 | B37: ='OBE Sheet'!D24 -> Fareed Ahmed | D37: ='OBE Sheet'!G24 -> 0 | E37: ='OBE Sheet'!L24 -> 0 | F37: ='OBE Sheet'!O24 -> 0 | G37: ='OBE Sheet'!T24 -> 0 | H37: ='OBE Sheet'!W24 -> 0 | I37: =SUM(D37:H37) -> 0 | J37: =VLOOKUP(I37,$H$9:$I$20,2,TRUE) -> F
... A68: ='OBE Sheet'!C55 -> 2023-CS-160 | B68: ='OBE Sheet'!D55 -> Muhammad Hanzla | D68: ='OBE Sheet'!G55 -> 5 | E68: ='OBE Sheet'!L55 -> 3.5 | F68: ='OBE Sheet'!O55 -> 7 | G68: ='OBE Sheet'!T55 -> 16 | H68: ='OBE Sheet'!W55 -> 10 | I68: =SUM(D68:H68) -> 41.5 | J68: =VLOOKUP(I68,$H$9:$I$20,2,TRUE) -> C+
A71: Teacher Incharge Signature | D71: Incharge Department Signature
A72: =H5 -> Mr. Abdul Basit | D72: ='OBE Sheet'!V74 -> (Engr. Dr. Muhammad Shahzad)

Sheet CLO & PLO
A1: CLO1 | B1: {=IFERROR(_xlfn._xlws.FILTER('OBE Sheet'!$E$10:$V$10,'CLO & PLO'!A1='OBE Sheet'!$E$11:$V$11),0)} -> 10 | C1: 7 | D1: 10 | K1: =SUM(B1:J1) -> 27 | N1: PLO1 | O1: {=IFERROR( _xlfn._xlws.FILTER('OBE Sheet'!$E$10:$W$10,'CLO & PLO'!N1='OBE Sheet'!$E$12:$W$12),0)} -> 0 | X1: =SUM(O1:W1) -> 0
A2: CLO2 | B2: {=IFERROR(_xlfn._xlws.FILTER('OBE Sheet'!$E$10:$V$10,'CLO & PLO'!A2='OBE Sheet'!$E$11:$V$11),0)} -> 20 | C2: 5 | K2: =SUM(B2:J2) -> 25 | N2: PLO2 | O2: {=IFERROR( _xlfn._xlws.FILTER('OBE Sheet'!$E$10:$W$10,'CLO & PLO'!N2='OBE Sheet'!$E$12:$W$12),0)} -> 10 | P2: 7 | Q2: 20 | R2: 3 | S2: 10 | T2: 20 | U2: 5 | X2: =SUM(O2:W2) -> 75
A3: CLO3 | B3: {=IFERROR(_xlfn._xlws.FILTER('OBE Sheet'!$E$10:$V$10,'CLO & PLO'!A3='OBE Sheet'!$E$11:$V$11),0)} -> 3 | C3: 20 | K3: =SUM(B3:J3) -> 23 | N3: PLO3 | O3: {=IFERROR( _xlfn._xlws.FILTER('OBE Sheet'!$E$10:$W$10,'CLO & PLO'!N3='OBE Sheet'!$E$12:$W$12),0)} -> 10 | P3: 10 | Q3: 5 | X3: =SUM(O3:W3) -> 25
A4: CLO4 | B4: {=IFERROR(_xlfn._xlws.FILTER('OBE Sheet'!$E$10:$V$10,'CLO & PLO'!A4='OBE Sheet'!$E$11:$V$11),0)} -> 10 | C4: 10 | D4: 5 | K4: =SUM(B4:J4) -> 25 | N4: PLO4 | O4: {=IFERROR( _xlfn._xlws.FILTER('OBE Sheet'!$E$10:$W$10,'CLO & PLO'!N4='OBE Sheet'!$E$12:$W$12),0)} -> 0 | X4: =SUM(O4:W4) -> 0
A5: CLO5 | B5: {=IFERROR(_xlfn._xlws.FILTER('OBE Sheet'!$E$10:$V$10,'CLO & PLO'!A5='OBE Sheet'!$E$11:$V$11),0)} -> 0 | K5: =SUM(B5:J5) -> 0 | N5: PLO5 | O5: {=IFERROR( _xlfn._xlws.FILTER('OBE Sheet'!$E$10:$W$10,'CLO & PLO'!N5='OBE Sheet'!$E$12:$W$12),0)} -> 0 | X5: =SUM(O5:W5) -> 0
A6: CLO6 | B6: {=IFERROR(_xlfn._xlws.FILTER('OBE Sheet'!$E$10:$V$10,'CLO & PLO'!A6='OBE Sheet'!$E$11:$V$11),0)} -> 0 | K6: =SUM(B6:J6) -> 0 | N6: PLO6 | O6: {=IFERROR( _xlfn._xlws.FILTER('OBE Sheet'!$E$10:$W$10,'CLO & PLO'!N6='OBE Sheet'!$E$12:$W$12),0)} -> 0 | X6: =SUM(O6:W6) -> 0
A7: CLO7 | B7: {=IFERROR(_xlfn._xlws.FILTER('OBE Sheet'!$E$10:$V$10,'CLO & PLO'!A7='OBE Sheet'!$E$11:$V$11),0)} -> 0 | K7: =SUM(B7:J7) -> 0 | N7: PLO7 | O7: {=IFERROR( _xlfn._xlws.FILTER('OBE Sheet'!$E$10:$W$10,'CLO & PLO'!N7='OBE Sheet'!$E$12:$W$12),0)} -> 0 | X7: =SUM(O7:W7) -> 0
A8: CLO8 | B8: {=IFERROR(_xlfn._xlws.FILTER('OBE Sheet'!$E$10:$V$10,'CLO & PLO'!A8='OBE Sheet'!$E$11:$V$11),0)} -> 0 | K8: =SUM(B8:J8) -> 0 | N8: PLO8 | O8: {=IFERROR( _xlfn._xlws.FILTER('OBE Sheet'!$E$10:$W$10,'CLO & PLO'!N8='OBE Sheet'!$E$12:$W$12),0)} -> 0 | X8: =SUM(O8:W8) -> 0
A9: CLO9 | B9: {=IFERROR(_xlfn._xlws.FILTER('OBE Sheet'!$E$10:$V$10,'CLO & PLO'!A9='OBE Sheet'!$E$11:$V$11),0)} -> 0 | K9: =SUM(B9:J9) -> 0 | N9: PLO9 | O9: {=IFERROR( _xlfn._xlws.FILTER('OBE Sheet'!$E$10:$W$10,'CLO & PLO'!N9='OBE Sheet'!$E$12:$W$12),0)} -> 0 | X9: =SUM(O9:W9) -> 0
A10: CLO10 | B10: {=IFERROR(_xlfn._xlws.FILTER('OBE Sheet'!$E$10:$V$10,'CLO & PLO'!A10='OBE Sheet'!$E$11:$V$11),0)} -> 0 | K10: =SUM(B10:J10) -> 0 | N10: PLO10 | O10: {=IFERROR( _xlfn._xlws.FILTER('OBE Sheet'!$E$10:$W$10,'CLO & PLO'!N10='OBE Sheet'!$E$12:$W$12),0)} -> 0 | X10: =SUM(O10:W10) -> 0
